Workbook

Sheet RAIZ
A1: FECHA | B1: 46301
A2: Etiquetas de fila | B2: San Cayetano | C2: Suc. Acaponeta | D2: Suc. Allende | E2: Suc. Amado Nervo | F2: Suc. Boulevard | G2: Suc. Compostela | H2: Suc. Dos de Agosto | I2: Suc. La Nueva Canasta | J2: Suc. León | K2: Suc. Mololoa | L2: Suc. Peñita | M2: Suc. Plaza | N2: Suc. Ruiz | O2: Suc. Sanblas | P2: Suc. Santa María del Oro | Q2: Suc. Santiago | R2: Suc. Santiago 2 | S2: Suc. Tecuala | T2: Suc. Tuxpan | U2: Suc. Varas | V2: Suc. Vistas | W2: Suc. Xalisco | X2: Villa Hidalgo | Y2: Total general
A3: DUO DURAZNO GDE DE CORAZON | B3: 0 | C3: 0 | D3: 0 | E3: 0 | F3: 0 | G3: 0 | H3: 0 | K3: 0 | M3: 0 | N3: 0 | O3: 0 | Q3: 0 | S3: 0 | T3: 0 | V3: 0 | W3: 0 | Y3: 0
A4: PETIT | B4: 0 | C4: 0 | D4: 0 | F4: 0 | G4: 0 | H4: 0 | K4: 0 | M4: 0 | N4: 0 | O4: 0 | Q4: 0 | T4: 0 | V4: 0 | W4: 0 | Y4: 0
A5: $15 PAN DULCE 25 PIEZAS | B5: 0 | C5: 0 | D5: 0 | E5: 0 | F5: 0 | G5: 0 | H5: 0 | J5: 0 | K5: 0 | L5: 0 | M5: 0 | N5: 0 | O5: 0 | P5: 0 | Q5: 0 | R5: 0 | S5: 0 | T5: 0 | U5: 0 | V5: 0 | W5: 0 | X5: 0 | Y5: 0
A6: $20 PAN DULCE 25 PIEZAS | B6: 0 | C6: 0 | D6: 0 | E6: 0 | F6: 0 | G6: 0 | H6: 0 | I6: 0 | J6: 0 | K6: 0 | L6: 0 | M6: 0 | N6: 0 | O6: 0 | P6: 0 | Q6: 0 | R6: 0 | S6: 0 | T6: 0 | U6: 0 | V6: 0 | W6: 0 | X6: 0 | Y6: 0
A7: 1 1/2 KG CHOCOLATE | B7: 0 | D7: 0 | E7: 0 | F7: 0 | G7: 0 | H7: 0 | M7: 0 | N7: 0 | O7: 0 | Q7: 0 | T7: 0 | V7: 0 | W7: 0 | Y7: 0
A8: 1 1/2 KG FANTASIA | B8: 0 | D8: 0 | E8: 0 | F8: 0 | G8: 0 | H8: 0 | K8: 0 | M8: 0 | N8: 0 | O8: 0 | Q8: 0 | T8: 0 | V8: 0 | W8: 0 | Y8: 0
A9: 1 1/2 KG PIÑERO | B9: 0 | D9: 0 | E9: 0 | F9: 0 | G9: 0 | H9: 0 | M9: 0 | N9: 0 | O9: 0 | Q9: 0 | T9: 0 | V9: 0 | W9: 0 | Y9: 0
A10: 1 KG CHOCOLATE SUPER FAMILIAR | B10: 0 | C10: 0 | D10: 0 | E10: 0 | F10: 0 | G10: 0 | H10: 0 | J10: 0 | K10: 0 | M10: 0 | N10: 0 | O10: 0 | P10: 0 | Q10: 0 | R10: 0 | T10: 0 | V10: 0 | W10: 0 | Y10: 0
A11: 1 KG DE GALLETA | B11: 0 | D11: 0 | E11: 0 | F11: 0 | G11: 0 | H11: 0 | K11: 0 | M11: 0 | N11: 0 | O11: 0 | Q11: 0 | T11: 0 | V11: 0 | W11: 0 | Y11: 0
A12: 1 KG PIÑERO SUPER FAMILIAR | B12: 0 | C12: 0 | D12: 0 | E12: 0 | F12: 0 | G12: 0 | H12: 0 | I12: 0 | J12: 0 | K12: 0 | M12: 0 | N12: 0 | O12: 0 | P12: 0 | Q12: 0 | R12: 0 | T12: 0 | U12: 0 | V12: 0 | W12: 0 | Y12: 0
A13: 1 KG VAINILLA SUPER FAMILIAR | B13: 0 | C13: 0 | D13: 0 | E13: 0 | F13: 0 | G13: 0 | H13: 0 | I13: 0 | J13: 0 | K13: 0 | M13: 0 | N13: 0 | O13: 0 | P13: 0 | Q13: 0 | R13: 0 | S13: 0 | T13: 0 | V13: 0 | W13: 0 | X13: 0 | Y13: 0
A14: 1/2 KG CHOCOLATE | B14: 0 | C14: 0 | D14: 0 | E14: 0 | F14: 0 | G14: 0 | H14: 0 | K14: 0 | M14: 0 | N14: 0 | O14: 0 | Q14: 0 | T14: 0 | V14: 0 | W14: 0 | Y14: 0
A15: 1/2 KG CHOCOLATE CASERO | B15: 0 | D15: 0 | F15: 0 | H15: 0 | M15: 0 | Q15: 0 | W15: 0 | Y15: 0
A16: 1/2 KG DE GALLETA | B16: 10 | C16: 11 | D16: 0 | E16: 40 | F16: 1 | G16: 5 | H16: 3 | I16: 0 | J16: 50 | K16: 10 | L16: 5 | M16: 10 | N16: 9 | O16: 2 | P16: 10 | Q16: 5 | R16: 3 | S16: 3 | T16: 5 | U16: 5 | V16: 12 | W16: 3 | X16: 6 | Y16: 208
A17: 1/2 KG PIÑERO | B17: 0 | C17: 0 | D17: 0 | E17: 0 | F17: 0 | G17: 0 | H17: 0 | K17: 0 | M17: 0 | N17: 0 | O17: 0 | Q17: 0 | T17: 0 | V17: 0 | W17: 0 | Y17: 0
A18: 1/2 KG VAINILLA | B18: 0 | C18: 0 | D18: 0 | E18: 0 | F18: 0 | G18: 0 | H18: 0 | K18: 0 | M18: 0 | N18: 0 | O18: 0 | Q18: 0 | T18: 0 | V18: 0 | W18: 0 | Y18: 0
A19: 1/2KG 3 LECHES PIÑERO | B19: 0 | D19: 0 | E19: 0 | F19: 0 | H19: 0 | M19: 0 | Q19: 0 | W19: 0 | Y19: 0
A20: 1/2KG CHOCOLATE 3 LECHES | B20: 0 | D20: 0 | F20: 0 | H20: 0 | M20: 0 | Q20: 0 | W20: 0 | Y20: 0
A21: 1/2KG COMBINADO 3 LECHES | B21: 0 | D21: 0 | F21: 0 | H21: 0 | M21: 0 | Q21: 0 | W21: 0 | Y21: 0
A22: 1/2KG VAINILLA CASERO | B22: 0 | D22: 0 | F22: 0 | H22: 0 | M22: 0 | Q22: 0 | W22: 0 | Y22: 0
A23: 1/2KG VAINILLA CON CHOCOLATE CASERO | B23: 0 | D23: 0 | F23: 0 | H23: 0 | M23: 0 | Q23: 0 | W23: 0 | Y23: 0
A24: 1/4 KG DE GALLETA | B24: 10 | C24: 10 | D24: 0 | E24: 40 | F24: 1 | G24: 4 | H24: 5 | I24: 0 | J24: 48 | K24: 10 | L24: 0 | M24: 8 | N24: 10 | O24: 3 | P24: 8 | Q24: 6 | R24: 4 | S24: 3 | T24: 5 | U24: 14 | V24: 10 | W24: 3 | X24: 8 | Y24: 210
A25: 11/2KG 3 LECHES PIÑERO | B25: 0 | D25: 0 | F25: 0 | H25: 0 | M25: 0 | Q25: 0 | W25: 0 | Y25: 0
A26: 11/2KG CHOCOLATE 3 LECHES | B26: 0 | D26: 0 | F26: 0 | H26: 0 | M26: 0 | Q26: 0 | W26: 0 | Y26: 0
A27: 11/2KG CHOCOLATE CASERO | B27: 0 | D27: 0 | F27: 0 | H27: 0 | M27: 0 | Q27: 0 | W27: 0 | Y27: 0
A28: 11/2KG COMBINADO 3 LECHES | B28: 0 | D28: 0 | F28: 0 | H28: 0 | M28: 0 | Q28: 0 | W28: 0 | Y28: 0
A29: 11/2KG COMBINADO CASERO | B29: 0 | D29: 0 | F29: 0 | H29: 0 | M29: 0 | Q29: 0 | W29: 0 | Y29: 0
A30: 11/2KG VAINILLA CASERO | B30: 0 | D30: 0 | F30: 0 | H30: 0 | M30: 0 | Q30: 0 | W30: 0 | Y30: 0
A31: 16 CM MMD CHOC | B31: 0 | D31: 0 | E31: 0 | F31: 0 | G31: 0 | H31: 0 | I31: 0 | K31: 0 | M31: 0 | N31: 0 | O31: 0 | Q31: 0 | T31: 0 | V31: 0 | W31: 0 | Y31: 0
A32: 16 CM MMD PIÑERO | B32: 0 | D32: 0 | E32: 0 | F32: 0 | G32: 0 | H32: 0 | I32: 0 | K32: 0 | M32: 0 | N32: 0 | O32: 0 | Q32: 0 | T32: 0 | V32: 0 | W32: 0 | Y32: 0
A33: 16 CM MMD VAINILLA | B33: 0 | D33: 0 | E33: 0 | F33: 0 | G33: 0 | H33: 0 | J33: 0 | K33: 0 | M33: 0 | N33: 0 | O33: 0 | Q33: 0 | T33: 0 | V33: 0 | W33: 0 | Y33: 0
A34: 1KG 3 LECHES PIÑERO | B34: 0 | D34: 0 | E34: 0 | F34: 0 | H34: 0 | M34: 0 | Q34: 0 | W34: 0 | Y34: 0
A35: 1KG CHOCOLATE 3 LECHES | B35: 0 | D35: 0 | E35: 0 | F35: 0 | H35: 0 | M35: 0 | O35: 0 | Q35: 0 | W35: 0 | Y35: 0
A36: 1KG CHOCOLATE CASERO | B36: 0 | D36: 0 | F36: 0 | H36: 0 | M36: 0 | Q36: 0 | W36: 0 | Y36: 0
A37: 1KG COMBINADO 3 LECHES | B37: 0 | D37: 0 | F37: 0 | H37: 0 | M37: 0 | Q37: 0 | W37: 0 | Y37: 0
A38: 1KG COMBINADO CASERO | B38: 0 | D38: 0 | F38: 0 | H38: 0 | M38: 0 | Q38: 0 | W38: 0 | Y38: 0
A39: 1KG VAINILLA CASERO | B39: 0 | D39: 0 | E39: 0 | F39: 0 | H39: 0 | M39: 0 | O39: 0 | Q39: 0 | W39: 0 | Y39: 0
A40: 2 DE 3/4 CHOCOLATE JUMBO - FAMILIAR | B40: 0 | C40: 0 | D40: 0 | E40: 0 | F40: 0 | G40: 0 | H40: 0 | J40: 0 | K40: 0 | M40: 0 | N40: 0 | O40: 0 | Q40: 0 | R40: 0 | T40: 0 | V40: 0 | W40: 0 | Y40: 0
...

Sheet Suc. Amado Nervo
A1: =RAIZ!B1 -> 46301 | D1: SUCURSAL | F1: Suc. Amado Nervo
A2: PRODUCTO | B2: CODIGO | C2: EXISTENCIA EN SUCURSAL | D2: STOCK DETERMINADO FIN SEMANA | E2: PROMEDIO DE DISTRIBUCIÓN | F2: PRODUCTO A COMPLETAR | G2: A SURTIR TICKET
A3: PIÑA GDE | B3: 02 | C3: =+IFERROR(VLOOKUP($A3,RAIZ!$A$3:$X$1500,MATCH('Suc. Amado Nervo'!$F$1,RAIZ!$A$2:$X$2,0),FALSE),0)-1-1 -> 1 | D3: 3 | E3: Puede variar de 3 a 4 pzas | F3: =IF(D3-C3>=0,D3-C3,0) -> 2 | G3: 2
A4: DURAZNO GDE | B4: 04 | C4: =+IFERROR(VLOOKUP($A4,RAIZ!$A$3:$X$1500,MATCH('Suc. Amado Nervo'!$F$1,RAIZ!$A$2:$X$2,0),FALSE),0) -> 2 | D4: 2 | F4: =IF(D4-C4>=0,D4-C4,0) -> 0
A5: 3 LECHES GDE | B5: 06 | C5: =+IFERROR(VLOOKUP($A5,RAIZ!$A$3:$X$1500,MATCH('Suc. Amado Nervo'!$F$1,RAIZ!$A$2:$X$2,0),FALSE),0) -> 2 | D5: 2 | F5: =IF(D5-C5>=0,D5-C5,0) -> 0
A6: FRUTAS GDE | B6: 03 | C6: =+IFERROR(VLOOKUP($A6,RAIZ!$A$3:$X$1500,MATCH('Suc. Amado Nervo'!$F$1,RAIZ!$A$2:$X$2,0),FALSE),0) -> 3 | D6: 3 | F6: =IF(D6-C6>=0,D6-C6,0) -> 0
A7: DUO DURAZNO GDE | B7: 13 | C7: =+IFERROR(VLOOKUP($A7,RAIZ!$A$3:$X$1500,MATCH('Suc. Amado Nervo'!$F$1,RAIZ!$A$2:$X$2,0),FALSE),0) -> 2 | D7: 2 | F7: =IF(D7-C7>=0,D7-C7,0) -> 0
A8: MOKA GDE | B8: 01 | C8: =+IFERROR(VLOOKUP($A8,RAIZ!$A$3:$X$1500,MATCH('Suc. Amado Nervo'!$F$1,RAIZ!$A$2:$X$2,0),FALSE),0)-1 -> 4 | D8: 5 | F8: =IF(D8-C8>=0,D8-C8,0) -> 1 | G8: 1
A9: NUTELA GDE | B9: 09 | C9: =+IFERROR(VLOOKUP($A9,RAIZ!$A$3:$X$1500,MATCH('Suc. Amado Nervo'!$F$1,RAIZ!$A$2:$X$2,0),FALSE),0) -> 2 | D9: 2 | F9: =IF(D9-C9>=0,D9-C9,0) -> 0
A10: CHOCOLATE GDE | B10: 07 | C10: =+IFERROR(VLOOKUP($A10,RAIZ!$A$3:$X$1500,MATCH('Suc. Amado Nervo'!$F$1,RAIZ!$A$2:$X$2,0),FALSE),0) -> 3 | D10: 3 | F10: =IF(D10-C10>=0,D10-C10,0) -> 0
A11: M & M GDE | B11: 36 | C11: =+IFERROR(VLOOKUP($A11,RAIZ!$A$3:$X$1500,MATCH('Suc. Amado Nervo'!$F$1,RAIZ!$A$2:$X$2,0),FALSE),0) -> 2 | D11: 2 | F11: =IF(D11-C11>=0,D11-C11,0) -> 0
C12: =+IFERROR(VLOOKUP($A12,RAIZ!$A$3:$X$1500,MATCH('Suc. Amado Nervo'!$F$1,RAIZ!$A$2:$X$2,0),FALSE),0) -> 0 | F12: =IF(D12-C12>=0,D12-C12,0) -> 0
C13: =+IFERROR(VLOOKUP($A13,RAIZ!$A$3:$X$1500,MATCH('Suc. Amado Nervo'!$F$1,RAIZ!$A$2:$X$2,0),FALSE),0) -> 0 | F13: =IF(D13-C13>=0,D13-C13,0) -> 0
C14: =+IFERROR(VLOOKUP($A14,RAIZ!$A$3:$X$1500,MATCH('Suc. Amado Nervo'!$F$1,RAIZ!$A$2:$X$2,0),FALSE),0) -> 0 | F14: =IF(D14-C14>=0,D14-C14,0) -> 0
C15: =+IFERROR(VLOOKUP($A15,RAIZ!$A$3:$X$1500,MATCH('Suc. Amado Nervo'!$F$1,RAIZ!$A$2:$X$2,0),FALSE),0) -> 0 | F15: =IF(D15-C15>=0,D15-C15,0) -> 0
C16: =+IFERROR(VLOOKUP($A16,RAIZ!$A$3:$X$1500,MATCH('Suc. Amado Nervo'!$F$1,RAIZ!$A$2:$X$2,0),FALSE),0) -> 0 | F16: =IF(D16-C16>=0,D16-C16,0) -> 0
C17: =+IFERROR(VLOOKUP($A17,RAIZ!$A$3:$X$1500,MATCH('Suc. Amado Nervo'!$F$1,RAIZ!$A$2:$X$2,0),FALSE),0) -> 0 | F17: =IF(D17-C17>=0,D17-C17,0) -> 0
A18: 3 LECHES GRANDES | C18: =SUM(C3:C17) -> 21 | D18: =SUM(D3:D17) -> 24 | E18: =SUM(E3:E17) -> 0 | F18: =SUM(F3:F17) -> 3 | G18: =SUM(G3:G17) -> 3
A19: TRES LECHES MEDIANO | B19: 04M | C19: =+IFERROR(VLOOKUP($A19,RAIZ!$A$3:$X$1500,MATCH('Suc. Amado Nervo'!$F$1,RAIZ!$A$2:$X$2,0),FALSE),0) -> 2 | D19: 2 | F19: =IF(D19-C19>=0,D19-C19,0) -> 0
A20: FRUTAS MED | B20: 23N | C20: =+IFERROR(VLOOKUP($A20,RAIZ!$A$3:$X$1500,MATCH('Suc. Amado Nervo'!$F$1,RAIZ!$A$2:$X$2,0),FALSE),0) -> 2 | D20: 2 | F20: =IF(D20-C20>=0,D20-C20,0) -> 0
A21: DUO DURAZNO MEDIANO | B21: 06M | C21: =+IFERROR(VLOOKUP($A21,RAIZ!$A$3:$X$1500,MATCH('Suc. Amado Nervo'!$F$1,RAIZ!$A$2:$X$2,0),FALSE),0) -> 2 | D21: 2 | F21: =IF(D21-C21>=0,D21-C21,0) -> 0
A22: PIÑA MED | B22: 08M | C22: =+IFERROR(VLOOKUP($A22,RAIZ!$A$3:$X$1500,MATCH('Suc. Amado Nervo'!$F$1,RAIZ!$A$2:$X$2,0),FALSE),0) -> 1 | D22: 2 | F22: =IF(D22-C22>=0,D22-C22,0) -> 1 | G22: 1
A23: CHOCOLATE MED | B23: 24N | C23: =+IFERROR(VLOOKUP($A23,RAIZ!$A$3:$X$1500,MATCH('Suc. Amado Nervo'!$F$1,RAIZ!$A$2:$X$2,0),FALSE),0) -> 0 | D23: 2 | F23: =IF(D23-C23>=0,D23-C23,0) -> 2 | G23: 2
A24: M & M MEDIANO | B24: 07M | C24: =+IFERROR(VLOOKUP($A24,RAIZ!$A$3:$X$1500,MATCH('Suc. Amado Nervo'!$F$1,RAIZ!$A$2:$X$2,0),FALSE),0) -> 1 | D24: 2 | F24: =IF(D24-C24>=0,D24-C24,0) -> 1
A25: MOKA MEDIANO | B25: 01M | C25: =+IFERROR(VLOOKUP($A25,RAIZ!$A$3:$X$1500,MATCH('Suc. Amado Nervo'!$F$1,RAIZ!$A$2:$X$2,0),FALSE),0) -> 4 | D25: 4 | F25: =IF(D25-C25>=0,D25-C25,0) -> 0
C26: =+IFERROR(VLOOKUP($A26,RAIZ!$A$3:$X$1500,MATCH('Suc. Amado Nervo'!$F$1,RAIZ!$A$2:$X$2,0),FALSE),0) -> 0 | F26: =IF(D26-C26>=0,D26-C26,0) -> 0
C27: =+IFERROR(VLOOKUP($A27,RAIZ!$A$3:$X$1500,MATCH('Suc. Amado Nervo'!$F$1,RAIZ!$A$2:$X$2,0),FALSE),0) -> 0 | F27: =IF(D27-C27>=0,D27-C27,0) -> 0
C28: =+IFERROR(VLOOKUP($A28,RAIZ!$A$3:$X$1500,MATCH('Suc. Amado Nervo'!$F$1,RAIZ!$A$2:$X$2,0),FALSE),0) -> 0 | F28: =IF(D28-C28>=0,D28-C28,0) -> 0
C29: =+IFERROR(VLOOKUP($A29,RAIZ!$A$3:$X$1500,MATCH('Suc. Amado Nervo'!$F$1,RAIZ!$A$2:$X$2,0),FALSE),0) -> 0 | F29: =IF(D29-C29>=0,D29-C29,0) -> 0
C30: =+IFERROR(VLOOKUP($A30,RAIZ!$A$3:$X$1500,MATCH('Suc. Amado Nervo'!$F$1,RAIZ!$A$2:$X$2,0),FALSE),0) -> 0 | F30: =IF(D30-C30>=0,D30-C30,0) -> 0
C31: =+IFERROR(VLOOKUP($A31,RAIZ!$A$3:$X$1500,MATCH('Suc. Amado Nervo'!$F$1,RAIZ!$A$2:$X$2,0),FALSE),0) -> 0 | F31: =IF(D31-C31>=0,D31-C31,0) -> 0
A32: 3 LECHES MEDIANOS | C32: =SUM(C19:C31) -> 12 | D32: =SUM(D19:D31) -> 16 | E32: =SUM(E19:E31) -> 0 | F32: =SUM(F19:F31) -> 4 | G32: =SUM(G19:G31) -> 3
A33: PIÑA CH | B33: 16 | C33: =+IFERROR(VLOOKUP($A33,RAIZ!$A$3:$X$1500,MATCH('Suc. Amado Nervo'!$F$1,RAIZ!$A$2:$X$2,0),FALSE),0)-1 -> 2 | D33: 3 | F33: =IF(D33-C33>=0,D33-C33,0) -> 1 | G33: 1
A34: DURAZNO CH | B34: 17 | C34: =+IFERROR(VLOOKUP($A34,RAIZ!$A$3:$X$1500,MATCH('Suc. Amado Nervo'!$F$1,RAIZ!$A$2:$X$2,0),FALSE),0) -> 3 | D34: 2 | F34: =IF(D34-C34>=0,D34-C34,0) -> 0
A35: FRESA CH | B35: 18 | C35: =+IFERROR(VLOOKUP($A35,RAIZ!$A$3:$X$1500,MATCH('Suc. Amado Nervo'!$F$1,RAIZ!$A$2:$X$2,0),FALSE),0) -> 2 | D35: 2 | F35: =IF(D35-C35>=0,D35-C35,0) -> 0
A36: 3 LECHES CH | B36: 19 | C36: =+IFERROR(VLOOKUP($A36,RAIZ!$A$3:$X$1500,MATCH('Suc. Amado Nervo'!$F$1,RAIZ!$A$2:$X$2,0),FALSE),0) -> 3 | D36: 2 | F36: =IF(D36-C36>=0,D36-C36,0) -> 0
A37: FRUTAS CH | B37: 20 | C37: =+IFERROR(VLOOKUP($A37,RAIZ!$A$3:$X$1500,MATCH('Suc. Amado Nervo'!$F$1,RAIZ!$A$2:$X$2,0),FALSE),0) -> 3 | D37: 3 | F37: =IF(D37-C37>=0,D37-C37,0) -> 0
A38: MOKA CH | B38: 23 | C38: =+IFERROR(VLOOKUP($A38,RAIZ!$A$3:$X$1500,MATCH('Suc. Amado Nervo'!$F$1,RAIZ!$A$2:$X$2,0),FALSE),0)-1 -> 2 | D38: 3 | F38: =IF(D38-C38>=0,D38-C38,0) -> 1 | G38: 1
A39: NUTELA CH | B39: 28 | C39: =+IFERROR(VLOOKUP($A39,RAIZ!$A$3:$X$1500,MATCH('Suc. Amado Nervo'!$F$1,RAIZ!$A$2:$X$2,0),FALSE),0) -> 1 | D39: 2 | F39: =IF(D39-C39>=0,D39-C39,0) -> 1 | G39: 1
A40: CHOCOLATE CH | B40: 25 | C40: =+IFERROR(VLOOKUP($A40,RAIZ!$A$3:$X$1500,MATCH('Suc. Amado Nervo'!$F$1,RAIZ!$A$2:$X$2,0),FALSE),0) -> 2 | D40: 2 | F40: =IF(D40-C40>=0,D40-C40,0) -> 0
...

Sheet Suc. León
A1: =RAIZ!B1 -> 46301 | D1: SUCURSAL | F1: Suc. León | H1: [ PLANTA León - Cantidad ]
A2: PRODUCTO | B2: CODIGO | C2: EXISTENCIA EN SUCURSAL | D2: STOCK DETERMINADO | E2: PROMEDIO DE DISTRIBUCIÓN | F2: PRODUCTO A COMPLETAR | G2: A SURTIR TICKET
A3: PIÑA GDE | B3: 02 | C3: =+IFERROR(VLOOKUP($A3,RAIZ!$A$3:$X$1500,MATCH('Suc. León'!$F$1,RAIZ!$A$2:$X$2,0),FALSE),0) -> 2 | D3: 3 | F3: =IF(D3-C3>=0,D3-C3,0) -> 1 | G3: 1
A4: DURAZNO GDE | B4: 04 | C4: =+IFERROR(VLOOKUP($A4,RAIZ!$A$3:$X$1500,MATCH('Suc. León'!$F$1,RAIZ!$A$2:$X$2,0),FALSE),0) -> 2 | D4: 2 | F4: =IF(D4-C4>=0,D4-C4,0) -> 0
A5: 3 LECHES GDE | B5: 06 | C5: =+IFERROR(VLOOKUP($A5,RAIZ!$A$3:$X$1500,MATCH('Suc. León'!$F$1,RAIZ!$A$2:$X$2,0),FALSE),0) -> 2 | D5: 2 | F5: =IF(D5-C5>=0,D5-C5,0) -> 0
A6: FRUTAS GDE | B6: 03 | C6: =+IFERROR(VLOOKUP($A6,RAIZ!$A$3:$X$1500,MATCH('Suc. León'!$F$1,RAIZ!$A$2:$X$2,0),FALSE),0) -> 3 | D6: 3 | F6: =IF(D6-C6>=0,D6-C6,0) -> 0
A7: DUO DURAZNO GDE | B7: 13 | C7: =+IFERROR(VLOOKUP($A7,RAIZ!$A$3:$X$1500,MATCH('Suc. León'!$F$1,RAIZ!$A$2:$X$2,0),FALSE),0) -> 2 | D7: 2 | F7: =IF(D7-C7>=0,D7-C7,0) -> 0
A8: MOKA GDE | B8: 01 | C8: =+IFERROR(VLOOKUP($A8,RAIZ!$A$3:$X$1500,MATCH('Suc. León'!$F$1,RAIZ!$A$2:$X$2,0),FALSE),0) -> 3 | D8: 4 | F8: =IF(D8-C8>=0,D8-C8,0) -> 1 | G8: 1
A9: NUTELA GDE | B9: 09 | C9: =+IFERROR(VLOOKUP($A9,RAIZ!$A$3:$X$1500,MATCH('Suc. León'!$F$1,RAIZ!$A$2:$X$2,0),FALSE),0) -> 2 | D9: 2 | F9: =IF(D9-C9>=0,D9-C9,0) -> 0
A10: CHOCOLATE GDE | B10: 07 | C10: =+IFERROR(VLOOKUP($A10,RAIZ!$A$3:$X$1500,MATCH('Suc. León'!$F$1,RAIZ!$A$2:$X$2,0),FALSE),0) -> 3 | D10: 3 | F10: =IF(D10-C10>=0,D10-C10,0) -> 0
A11: M & M GDE | B11: 36 | C11: =+IFERROR(VLOOKUP($A11,RAIZ!$A$3:$X$1500,MATCH('Suc. León'!$F$1,RAIZ!$A$2:$X$2,0),FALSE),0) -> 2 | D11: 2 | F11: =IF(D11-C11>=0,D11-C11,0) -> 0
C12: =+IFERROR(VLOOKUP($A12,RAIZ!$A$3:$X$1500,MATCH('Suc. León'!$F$1,RAIZ!$A$2:$X$2,0),FALSE),0) -> 0 | F12: =IF(D12-C12>=0,D12-C12,0) -> 0
C13: =+IFERROR(VLOOKUP($A13,RAIZ!$A$3:$X$1500,MATCH('Suc. León'!$F$1,RAIZ!$A$2:$X$2,0),FALSE),0) -> 0 | F13: =IF(D13-C13>=0,D13-C13,0) -> 0
C14: =+IFERROR(VLOOKUP($A14,RAIZ!$A$3:$X$1500,MATCH('Suc. León'!$F$1,RAIZ!$A$2:$X$2,0),FALSE),0) -> 0 | F14: =IF(D14-C14>=0,D14-C14,0) -> 0
C15: =+IFERROR(VLOOKUP($A15,RAIZ!$A$3:$X$1500,MATCH('Suc. León'!$F$1,RAIZ!$A$2:$X$2,0),FALSE),0) -> 0 | F15: =IF(D15-C15>=0,D15-C15,0) -> 0
C16: =+IFERROR(VLOOKUP($A16,RAIZ!$A$3:$X$1500,MATCH('Suc. León'!$F$1,RAIZ!$A$2:$X$2,0),FALSE),0) -> 0 | F16: =IF(D16-C16>=0,D16-C16,0) -> 0
C17: =+IFERROR(VLOOKUP($A17,RAIZ!$A$3:$X$1500,MATCH('Suc. León'!$F$1,RAIZ!$A$2:$X$2,0),FALSE),0) -> 0 | F17: =IF(D17-C17>=0,D17-C17,0) -> 0
A18: 3 LECHES GRANDES | C18: =SUM(C3:C17) -> 21 | D18: =SUM(D3:D17) -> 23 | E18: 0 | F18: =SUM(F3:F17) -> 2 | G18: =SUM(G3:G17) -> 2
A19: TRES LECHES MEDIANO | B19: 04M | C19: =+IFERROR(VLOOKUP($A19,RAIZ!$A$3:$X$1500,MATCH('Suc. León'!$F$1,RAIZ!$A$2:$X$2,0),FALSE),0) -> 2 | D19: 2 | F19: =IF(D19-C19>=0,D19-C19,0) -> 0
A20: FRUTAS MED | B20: 23N | C20: =+IFERROR(VLOOKUP($A20,RAIZ!$A$3:$X$1500,MATCH('Suc. León'!$F$1,RAIZ!$A$2:$X$2,0),FALSE),0) -> 2 | D20: 3 | F20: =IF(D20-C20>=0,D20-C20,0) -> 1 | G20: 1
A21: DUO DURAZNO MEDIANO | B21: 06M | C21: =+IFERROR(VLOOKUP($A21,RAIZ!$A$3:$X$1500,MATCH('Suc. León'!$F$1,RAIZ!$A$2:$X$2,0),FALSE),0) -> 0 | D21: 2 | F21: =IF(D21-C21>=0,D21-C21,0) -> 2 | G21: 2
A22: PIÑA MED | B22: 08M | C22: =+IFERROR(VLOOKUP($A22,RAIZ!$A$3:$X$1500,MATCH('Suc. León'!$F$1,RAIZ!$A$2:$X$2,0),FALSE),0) -> 2 | D22: 2 | F22: =IF(D22-C22>=0,D22-C22,0) -> 0
A23: CHOCOLATE MED | B23: 24N | C23: =+IFERROR(VLOOKUP($A23,RAIZ!$A$3:$X$1500,MATCH('Suc. León'!$F$1,RAIZ!$A$2:$X$2,0),FALSE),0) -> 0 | D23: 3 | F23: =IF(D23-C23>=0,D23-C23,0) -> 3 | G23: 3
A24: M & M MEDIANO | B24: 07M | C24: =+IFERROR(VLOOKUP($A24,RAIZ!$A$3:$X$1500,MATCH('Suc. León'!$F$1,RAIZ!$A$2:$X$2,0),FALSE),0) -> 0 | D24: 2 | F24: =IF(D24-C24>=0,D24-C24,0) -> 2
A25: MOKA MEDIANO | B25: 01M | C25: =+IFERROR(VLOOKUP($A25,RAIZ!$A$3:$X$1500,MATCH('Suc. León'!$F$1,RAIZ!$A$2:$X$2,0),FALSE),0) -> 4 | D25: 4 | F25: =IF(D25-C25>=0,D25-C25,0) -> 0
C26: =+IFERROR(VLOOKUP($A26,RAIZ!$A$3:$X$1500,MATCH('Suc. León'!$F$1,RAIZ!$A$2:$X$2,0),FALSE),0) -> 0 | F26: =IF(D26-C26>=0,D26-C26,0) -> 0
C27: =+IFERROR(VLOOKUP($A27,RAIZ!$A$3:$X$1500,MATCH('Suc. León'!$F$1,RAIZ!$A$2:$X$2,0),FALSE),0) -> 0 | F27: =IF(D27-C27>=0,D27-C27,0) -> 0
C28: =+IFERROR(VLOOKUP($A28,RAIZ!$A$3:$X$1500,MATCH('Suc. León'!$F$1,RAIZ!$A$2:$X$2,0),FALSE),0) -> 0 | F28: =IF(D28-C28>=0,D28-C28,0) -> 0
C29: =+IFERROR(VLOOKUP($A29,RAIZ!$A$3:$X$1500,MATCH('Suc. León'!$F$1,RAIZ!$A$2:$X$2,0),FALSE),0) -> 0 | F29: =IF(D29-C29>=0,D29-C29,0) -> 0
C30: =+IFERROR(VLOOKUP($A30,RAIZ!$A$3:$X$1500,MATCH('Suc. León'!$F$1,RAIZ!$A$2:$X$2,0),FALSE),0) -> 0 | F30: =IF(D30-C30>=0,D30-C30,0) -> 0
C31: =+IFERROR(VLOOKUP($A31,RAIZ!$A$3:$X$1500,MATCH('Suc. León'!$F$1,RAIZ!$A$2:$X$2,0),FALSE),0) -> 0 | F31: =IF(D31-C31>=0,D31-C31,0) -> 0
A32: 3 LECHES MEDIANOS | C32: =SUM(C19:C31) -> 10 | D32: =SUM(D19:D31) -> 18 | E32: 0 | F32: =SUM(F19:F31) -> 8 | G32: =SUM(G19:G31) -> 6
A33: PIÑA CH | B33: 16 | C33: =+IFERROR(VLOOKUP($A33,RAIZ!$A$3:$X$1500,MATCH('Suc. León'!$F$1,RAIZ!$A$2:$X$2,0),FALSE),0) -> 3 | D33: 3 | F33: =IF(D33-C33>=0,D33-C33,0) -> 0
A34: DURAZNO CH | B34: 17 | C34: =+IFERROR(VLOOKUP($A34,RAIZ!$A$3:$X$1500,MATCH('Suc. León'!$F$1,RAIZ!$A$2:$X$2,0),FALSE),0) -> 2 | D34: 2 | F34: =IF(D34-C34>=0,D34-C34,0) -> 0
A35: FRESA CH | B35: 18 | C35: =+IFERROR(VLOOKUP($A35,RAIZ!$A$3:$X$1500,MATCH('Suc. León'!$F$1,RAIZ!$A$2:$X$2,0),FALSE),0) -> 1 | D35: 2 | F35: =IF(D35-C35>=0,D35-C35,0) -> 1 | G35: 1
A36: 3 LECHES CH | B36: 19 | C36: =+IFERROR(VLOOKUP($A36,RAIZ!$A$3:$X$1500,MATCH('Suc. León'!$F$1,RAIZ!$A$2:$X$2,0),FALSE),0) -> 2 | D36: 2 | F36: =IF(D36-C36>=0,D36-C36,0) -> 0
A37: FRUTAS CH | B37: 20 | C37: =+IFERROR(VLOOKUP($A37,RAIZ!$A$3:$X$1500,MATCH('Suc. León'!$F$1,RAIZ!$A$2:$X$2,0),FALSE),0) -> 3 | D37: 3 | F37: =IF(D37-C37>=0,D37-C37,0) -> 0
A38: MOKA CH | B38: 23 | C38: =+IFERROR(VLOOKUP($A38,RAIZ!$A$3:$X$1500,MATCH('Suc. León'!$F$1,RAIZ!$A$2:$X$2,0),FALSE),0) -> 3 | D38: 3 | F38: =IF(D38-C38>=0,D38-C38,0) -> 0
A39: NUTELA CH | B39: 28 | C39: =+IFERROR(VLOOKUP($A39,RAIZ!$A$3:$X$1500,MATCH('Suc. León'!$F$1,RAIZ!$A$2:$X$2,0),FALSE),0) -> 2 | D39: 2 | F39: =IF(D39-C39>=0,D39-C39,0) -> 0
A40: CHOCOLATE CH | B40: 25 | C40: =+IFERROR(VLOOKUP($A40,RAIZ!$A$3:$X$1500,MATCH('Suc. León'!$F$1,RAIZ!$A$2:$X$2,0),FALSE),0) -> 3 | D40: 3 | F40: =IF(D40-C40>=0,D40-C40,0) -> 0
...

Sheet Suc. Vistas
A1: =RAIZ!B1 -> 46301 | D1: SUCURSAL | F1: Suc. Vistas | H1: [ Suc. Vistas - Cantidad ]
A2: PRODUCTO | B2: CODIGO | C2: EXISTENCIA EN SUCURSAL | D2: STOCK DETERMINADO | E2: PROMEDIO DE DISTRIBUCIÓN | F2: PRODUCTO A COMPLETAR | G2: A SURTIR TICKET
A3: PIÑA GDE | B3: 02 | C3: =+IFERROR(VLOOKUP($A3,RAIZ!$A$3:$X$1500,MATCH('Suc. Vistas'!$F$1,RAIZ!$A$2:$X$2,0),FALSE),0) -> 1 | D3: 2 | F3: =IF(D3-C3>=0,D3-C3,0) -> 1 | G3: 1
A4: DURAZNO GDE | B4: 04 | C4: =+IFERROR(VLOOKUP($A4,RAIZ!$A$3:$X$1500,MATCH('Suc. Vistas'!$F$1,RAIZ!$A$2:$X$2,0),FALSE),0) -> 2 | D4: 2 | F4: =IF(D4-C4>=0,D4-C4,0) -> 0
A5: 3 LECHES GDE | B5: 06 | C5: =+IFERROR(VLOOKUP($A5,RAIZ!$A$3:$X$1500,MATCH('Suc. Vistas'!$F$1,RAIZ!$A$2:$X$2,0),FALSE),0) -> 2 | D5: 2 | F5: =IF(D5-C5>=0,D5-C5,0) -> 0
A6: FRUTAS GDE | B6: 03 | C6: =+IFERROR(VLOOKUP($A6,RAIZ!$A$3:$X$1500,MATCH('Suc. Vistas'!$F$1,RAIZ!$A$2:$X$2,0),FALSE),0) -> 2 | D6: 4 | F6: =IF(D6-C6>=0,D6-C6,0) -> 2 | G6: 2
A7: DUO DURAZNO GDE | B7: 13 | C7: =+IFERROR(VLOOKUP($A7,RAIZ!$A$3:$X$1500,MATCH('Suc. Vistas'!$F$1,RAIZ!$A$2:$X$2,0),FALSE),0) -> 2 | D7: 2 | F7: =IF(D7-C7>=0,D7-C7,0) -> 0
A8: MOKA GDE | B8: 01 | C8: =+IFERROR(VLOOKUP($A8,RAIZ!$A$3:$X$1500,MATCH('Suc. Vistas'!$F$1,RAIZ!$A$2:$X$2,0),FALSE),0) -> 2 | D8: 4 | F8: =IF(D8-C8>=0,D8-C8,0) -> 2 | G8: 2
A9: NUTELA GDE | B9: 09 | C9: =+IFERROR(VLOOKUP($A9,RAIZ!$A$3:$X$1500,MATCH('Suc. Vistas'!$F$1,RAIZ!$A$2:$X$2,0),FALSE),0) -> 1 | D9: 2 | F9: =IF(D9-C9>=0,D9-C9,0) -> 1 | G9: 1
A10: CHOCOLATE GDE | B10: 07 | C10: =+IFERROR(VLOOKUP($A10,RAIZ!$A$3:$X$1500,MATCH('Suc. Vistas'!$F$1,RAIZ!$A$2:$X$2,0),FALSE),0) -> 4 | D10: 4 | F10: =IF(D10-C10>=0,D10-C10,0) -> 0
A11: M & M GDE | B11: 36 | C11: =+IFERROR(VLOOKUP($A11,RAIZ!$A$3:$X$1500,MATCH('Suc. Vistas'!$F$1,RAIZ!$A$2:$X$2,0),FALSE),0) -> 1 | D11: 2 | F11: =IF(D11-C11>=0,D11-C11,0) -> 1 | G11: 1
C12: =+IFERROR(VLOOKUP($A12,RAIZ!$A$3:$X$1500,MATCH('Suc. Vistas'!$F$1,RAIZ!$A$2:$X$2,0),FALSE),0) -> 0 | F12: =IF(D12-C12>=0,D12-C12,0) -> 0
C13: =+IFERROR(VLOOKUP($A13,RAIZ!$A$3:$X$1500,MATCH('Suc. Vistas'!$F$1,RAIZ!$A$2:$X$2,0),FALSE),0) -> 0 | F13: =IF(D13-C13>=0,D13-C13,0) -> 0
C14: =+IFERROR(VLOOKUP($A14,RAIZ!$A$3:$X$1500,MATCH('Suc. Vistas'!$F$1,RAIZ!$A$2:$X$2,0),FALSE),0) -> 0 | F14: =IF(D14-C14>=0,D14-C14,0) -> 0
C15: =+IFERROR(VLOOKUP($A15,RAIZ!$A$3:$X$1500,MATCH('Suc. Vistas'!$F$1,RAIZ!$A$2:$X$2,0),FALSE),0) -> 0 | F15: =IF(D15-C15>=0,D15-C15,0) -> 0
C16: =+IFERROR(VLOOKUP($A16,RAIZ!$A$3:$X$1500,MATCH('Suc. Vistas'!$F$1,RAIZ!$A$2:$X$2,0),FALSE),0) -> 0 | F16: =IF(D16-C16>=0,D16-C16,0) -> 0
C17: =+IFERROR(VLOOKUP($A17,RAIZ!$A$3:$X$1500,MATCH('Suc. Vistas'!$F$1,RAIZ!$A$2:$X$2,0),FALSE),0) -> 0 | F17: =IF(D17-C17>=0,D17-C17,0) -> 0
A18: 3 LECHES GRANDES | C18: =SUM(C3:C17) -> 17 | D18: =SUM(D3:D17) -> 24 | E18: =SUM(E3:E17) -> 0 | F18: =SUM(F3:F17) -> 7 | G18: =SUM(G3:G17) -> 7
A19: TRES LECHES MEDIANO | B19: 04M | C19: =+IFERROR(VLOOKUP($A19,RAIZ!$A$3:$X$1500,MATCH('Suc. Vistas'!$F$1,RAIZ!$A$2:$X$2,0),FALSE),0) -> 1 | D19: 2 | F19: =IF(D19-C19>=0,D19-C19,0) -> 1 | G19: 1
A20: FRUTAS MED | B20: 23N | C20: =+IFERROR(VLOOKUP($A20,RAIZ!$A$3:$X$1500,MATCH('Suc. Vistas'!$F$1,RAIZ!$A$2:$X$2,0),FALSE),0) -> 2 | D20: 4 | F20: =IF(D20-C20>=0,D20-C20,0) -> 2 | G20: 2
A21: DUO DURAZNO MEDIANO | B21: 06M | C21: =+IFERROR(VLOOKUP($A21,RAIZ!$A$3:$X$1500,MATCH('Suc. Vistas'!$F$1,RAIZ!$A$2:$X$2,0),FALSE),0) -> 1 | D21: 2 | F21: =IF(D21-C21>=0,D21-C21,0) -> 1 | G21: 1
A22: PIÑA MED | B22: 08M | C22: =+IFERROR(VLOOKUP($A22,RAIZ!$A$3:$X$1500,MATCH('Suc. Vistas'!$F$1,RAIZ!$A$2:$X$2,0),FALSE),0) -> 3 | D22: 3 | F22: =IF(D22-C22>=0,D22-C22,0) -> 0
A23: CHOCOLATE MED | B23: 24N | C23: =+IFERROR(VLOOKUP($A23,RAIZ!$A$3:$X$1500,MATCH('Suc. Vistas'!$F$1,RAIZ!$A$2:$X$2,0),FALSE),0) -> 3 | D23: 4 | F23: =IF(D23-C23>=0,D23-C23,0) -> 1 | G23: 1
A24: M & M MEDIANO | B24: 07M | C24: =+IFERROR(VLOOKUP($A24,RAIZ!$A$3:$X$1500,MATCH('Suc. Vistas'!$F$1,RAIZ!$A$2:$X$2,0),FALSE),0) -> 0 | D24: 2 | F24: =IF(D24-C24>=0,D24-C24,0) -> 2
A25: MOKA MEDIANO | B25: 01M | C25: =+IFERROR(VLOOKUP($A25,RAIZ!$A$3:$X$1500,MATCH('Suc. Vistas'!$F$1,RAIZ!$A$2:$X$2,0),FALSE),0) -> 0 | D25: 4 | F25: =IF(D25-C25>=0,D25-C25,0) -> 4 | G25: 4
C26: =+IFERROR(VLOOKUP($A26,RAIZ!$A$3:$X$1500,MATCH('Suc. Vistas'!$F$1,RAIZ!$A$2:$X$2,0),FALSE),0) -> 0 | F26: =IF(D26-C26>=0,D26-C26,0) -> 0
C27: =+IFERROR(VLOOKUP($A27,RAIZ!$A$3:$X$1500,MATCH('Suc. Vistas'!$F$1,RAIZ!$A$2:$X$2,0),FALSE),0) -> 0 | F27: =IF(D27-C27>=0,D27-C27,0) -> 0
C28: =+IFERROR(VLOOKUP($A28,RAIZ!$A$3:$X$1500,MATCH('Suc. Vistas'!$F$1,RAIZ!$A$2:$X$2,0),FALSE),0) -> 0 | F28: =IF(D28-C28>=0,D28-C28,0) -> 0
C29: =+IFERROR(VLOOKUP($A29,RAIZ!$A$3:$X$1500,MATCH('Suc. Vistas'!$F$1,RAIZ!$A$2:$X$2,0),FALSE),0) -> 0 | F29: =IF(D29-C29>=0,D29-C29,0) -> 0
C30: =+IFERROR(VLOOKUP($A30,RAIZ!$A$3:$X$1500,MATCH('Suc. Vistas'!$F$1,RAIZ!$A$2:$X$2,0),FALSE),0) -> 0 | F30: =IF(D30-C30>=0,D30-C30,0) -> 0
C31: =+IFERROR(VLOOKUP($A31,RAIZ!$A$3:$X$1500,MATCH('Suc. Vistas'!$F$1,RAIZ!$A$2:$X$2,0),FALSE),0) -> 0 | F31: =IF(D31-C31>=0,D31-C31,0) -> 0
A32: 3 LECHES MEDIANOS | C32: =SUM(C19:C31) -> 10 | D32: =SUM(D19:D31) -> 21 | E32: =SUM(E19:E31) -> 0 | F32: =SUM(F19:F31) -> 11 | G32: =SUM(G19:G31) -> 9
A33: PIÑA CH | B33: 16 | C33: =+IFERROR(VLOOKUP($A33,RAIZ!$A$3:$X$1500,MATCH('Suc. Vistas'!$F$1,RAIZ!$A$2:$X$2,0),FALSE),0) -> 0 | D33: 2 | F33: =IF(D33-C33>=0,D33-C33,0) -> 2 | G33: 2
A34: DURAZNO CH | B34: 17 | C34: =+IFERROR(VLOOKUP($A34,RAIZ!$A$3:$X$1500,MATCH('Suc. Vistas'!$F$1,RAIZ!$A$2:$X$2,0),FALSE),0) -> 2 | D34: 2 | F34: =IF(D34-C34>=0,D34-C34,0) -> 0
A35: FRESA CH | B35: 18 | C35: =+IFERROR(VLOOKUP($A35,RAIZ!$A$3:$X$1500,MATCH('Suc. Vistas'!$F$1,RAIZ!$A$2:$X$2,0),FALSE),0) -> 1 | D35: 2 | F35: =IF(D35-C35>=0,D35-C35,0) -> 1 | G35: 1
A36: 3 LECHES CH | B36: 19 | C36: =+IFERROR(VLOOKUP($A36,RAIZ!$A$3:$X$1500,MATCH('Suc. Vistas'!$F$1,RAIZ!$A$2:$X$2,0),FALSE),0) -> 1 | D36: 2 | F36: =IF(D36-C36>=0,D36-C36,0) -> 1 | G36: 1
A37: FRUTAS CH | B37: 20 | C37: =+IFERROR(VLOOKUP($A37,RAIZ!$A$3:$X$1500,MATCH('Suc. Vistas'!$F$1,RAIZ!$A$2:$X$2,0),FALSE),0) -> 0 | D37: 4 | F37: =IF(D37-C37>=0,D37-C37,0) -> 4 | G37: 4
A38: MOKA CH | B38: 23 | C38: =+IFERROR(VLOOKUP($A38,RAIZ!$A$3:$X$1500,MATCH('Suc. Vistas'!$F$1,RAIZ!$A$2:$X$2,0),FALSE),0) -> 0 | D38: 4 | F38: =IF(D38-C38>=0,D38-C38,0) -> 4 | G38: 4
A39: NUTELA CH | B39: 28 | C39: =+IFERROR(VLOOKUP($A39,RAIZ!$A$3:$X$1500,MATCH('Suc. Vistas'!$F$1,RAIZ!$A$2:$X$2,0),FALSE),0) -> 1 | D39: 2 | F39: =IF(D39-C39>=0,D39-C39,0) -> 1 | G39: 1
A40: CHOCOLATE CH | B40: 25 | C40: =+IFERROR(VLOOKUP($A40,RAIZ!$A$3:$X$1500,MATCH('Suc. Vistas'!$F$1,RAIZ!$A$2:$X$2,0),FALSE),0) -> 0 | D40: 4 | F40: =IF(D40-C40>=0,D40-C40,0) -> 4 | G40: 4
...

Sheet Suc. Xalisco
A1: =RAIZ!B1 -> 46301 | D1: SUCURSAL | F1: Suc. Xalisco | H1: [ Suc. Xalisco - Cantidad ]
A2: PRODUCTO | B2: CODIGO | C2: EXISTENCIA EN SUCURSAL | D2: STOCK DETERMINADO | E2: PROMEDIO DE DISTRIBUCIÓN | F2: PRODUCTO A COMPLETAR | G2: A SURTIR TICKET | H2: MARTES
A3: PIÑA GDE | B3: 02 | C3: =+IFERROR(VLOOKUP($A3,RAIZ!$A$3:$X$1500,MATCH('Suc. Xalisco'!$F$1,RAIZ!$A$2:$X$2,0),FALSE),0) -> 1 | D3: 2 | F3: =IF(D3-C3>=0,D3-C3,0) -> 1 | G3: 1
A4: DURAZNO GDE | B4: 04 | C4: =+IFERROR(VLOOKUP($A4,RAIZ!$A$3:$X$1500,MATCH('Suc. Xalisco'!$F$1,RAIZ!$A$2:$X$2,0),FALSE),0) -> 1 | D4: 2 | F4: =IF(D4-C4>=0,D4-C4,0) -> 1 | G4: 1
A5: 3 LECHES GDE | B5: 06 | C5: =+IFERROR(VLOOKUP($A5,RAIZ!$A$3:$X$1500,MATCH('Suc. Xalisco'!$F$1,RAIZ!$A$2:$X$2,0),FALSE),0) -> 2 | D5: 2 | F5: =IF(D5-C5>=0,D5-C5,0) -> 0
A6: FRUTAS GDE | B6: 03 | C6: =+IFERROR(VLOOKUP($A6,RAIZ!$A$3:$X$1500,MATCH('Suc. Xalisco'!$F$1,RAIZ!$A$2:$X$2,0),FALSE),0) -> 3 | D6: 3 | F6: =IF(D6-C6>=0,D6-C6,0) -> 0
A7: DUO DURAZNO GDE | B7: 13 | C7: =+IFERROR(VLOOKUP($A7,RAIZ!$A$3:$X$1500,MATCH('Suc. Xalisco'!$F$1,RAIZ!$A$2:$X$2,0),FALSE),0) -> 1 | D7: 2 | F7: =IF(D7-C7>=0,D7-C7,0) -> 1 | G7: 1
A8: MOKA GDE | B8: 01 | C8: =+IFERROR(VLOOKUP($A8,RAIZ!$A$3:$X$1500,MATCH('Suc. Xalisco'!$F$1,RAIZ!$A$2:$X$2,0),FALSE),0) -> 3 | D8: 3 | F8: =IF(D8-C8>=0,D8-C8,0) -> 0
A9: NUTELA GDE | B9: 09 | C9: =+IFERROR(VLOOKUP($A9,RAIZ!$A$3:$X$1500,MATCH('Suc. Xalisco'!$F$1,RAIZ!$A$2:$X$2,0),FALSE),0) -> 2 | D9: 2 | F9: =IF(D9-C9>=0,D9-C9,0) -> 0
A10: CHOCOLATE GDE | B10: 07 | C10: =+IFERROR(VLOOKUP($A10,RAIZ!$A$3:$X$1500,MATCH('Suc. Xalisco'!$F$1,RAIZ!$A$2:$X$2,0),FALSE),0) -> 1 | D10: 2 | F10: =IF(D10-C10>=0,D10-C10,0) -> 1 | G10: 1
A11: M & M GDE | B11: 36 | C11: =+IFERROR(VLOOKUP($A11,RAIZ!$A$3:$X$1500,MATCH('Suc. Xalisco'!$F$1,RAIZ!$A$2:$X$2,0),FALSE),0) -> 0 | D11: 2 | F11: =IF(D11-C11>=0,D11-C11,0) -> 2 | G11: 2
C12: =+IFERROR(VLOOKUP($A12,RAIZ!$A$3:$X$1500,MATCH('Suc. Xalisco'!$F$1,RAIZ!$A$2:$X$2,0),FALSE),0) -> 0 | F12: =IF(D12-C12>=0,D12-C12,0) -> 0
C13: =+IFERROR(VLOOKUP($A13,RAIZ!$A$3:$X$1500,MATCH('Suc. Xalisco'!$F$1,RAIZ!$A$2:$X$2,0),FALSE),0) -> 0 | F13: =IF(D13-C13>=0,D13-C13,0) -> 0
C14: =+IFERROR(VLOOKUP($A14,RAIZ!$A$3:$X$1500,MATCH('Suc. Xalisco'!$F$1,RAIZ!$A$2:$X$2,0),FALSE),0) -> 0 | F14: =IF(D14-C14>=0,D14-C14,0) -> 0
C15: =+IFERROR(VLOOKUP($A15,RAIZ!$A$3:$X$1500,MATCH('Suc. Xalisco'!$F$1,RAIZ!$A$2:$X$2,0),FALSE),0) -> 0 | F15: =IF(D15-C15>=0,D15-C15,0) -> 0
C16: =+IFERROR(VLOOKUP($A16,RAIZ!$A$3:$X$1500,MATCH('Suc. Xalisco'!$F$1,RAIZ!$A$2:$X$2,0),FALSE),0) -> 0 | F16: =IF(D16-C16>=0,D16-C16,0) -> 0
C17: =+IFERROR(VLOOKUP($A17,RAIZ!$A$3:$X$1500,MATCH('Suc. Xalisco'!$F$1,RAIZ!$A$2:$X$2,0),FALSE),0) -> 0 | F17: =IF(D17-C17>=0,D17-C17,0) -> 0
A18: 3 LECHES GRANDES | C18: =SUM(C3:C17) -> 14 | D18: =SUM(D3:D17) -> 20 | E18: =SUM(E3:E17) -> 0 | F18: =SUM(F3:F17) -> 6 | G18: =SUM(G3:G17) -> 6
A19: TRES LECHES MEDIANO | B19: 04M | C19: =+IFERROR(VLOOKUP($A19,RAIZ!$A$3:$X$1500,MATCH('Suc. Xalisco'!$F$1,RAIZ!$A$2:$X$2,0),FALSE),0) -> 1 | D19: 1 | F19: =IF(D19-C19>=0,D19-C19,0) -> 0
A20: FRUTAS MED | B20: 23N | C20: =+IFERROR(VLOOKUP($A20,RAIZ!$A$3:$X$1500,MATCH('Suc. Xalisco'!$F$1,RAIZ!$A$2:$X$2,0),FALSE),0) -> 2 | D20: 3 | F20: =IF(D20-C20>=0,D20-C20,0) -> 1 | G20: 1
A21: DUO DURAZNO MEDIANO | B21: 06M | C21: =+IFERROR(VLOOKUP($A21,RAIZ!$A$3:$X$1500,MATCH('Suc. Xalisco'!$F$1,RAIZ!$A$2:$X$2,0),FALSE),0) -> 1 | D21: 1 | F21: =IF(D21-C21>=0,D21-C21,0) -> 0
A22: PIÑA MED | B22: 08M | C22: =+IFERROR(VLOOKUP($A22,RAIZ!$A$3:$X$1500,MATCH('Suc. Xalisco'!$F$1,RAIZ!$A$2:$X$2,0),FALSE),0) -> 1 | D22: 2 | F22: =IF(D22-C22>=0,D22-C22,0) -> 1 | G22: 1
A23: CHOCOLATE MED | B23: 24N | C23: =+IFERROR(VLOOKUP($A23,RAIZ!$A$3:$X$1500,MATCH('Suc. Xalisco'!$F$1,RAIZ!$A$2:$X$2,0),FALSE),0) -> 2 | D23: 3 | F23: =IF(D23-C23>=0,D23-C23,0) -> 1 | G23: 1
A24: M & M MEDIANO | B24: 07M | C24: =+IFERROR(VLOOKUP($A24,RAIZ!$A$3:$X$1500,MATCH('Suc. Xalisco'!$F$1,RAIZ!$A$2:$X$2,0),FALSE),0) -> 0 | D24: 1 | F24: =IF(D24-C24>=0,D24-C24,0) -> 1
A25: MOKA MEDIANO | B25: 01M | C25: =+IFERROR(VLOOKUP($A25,RAIZ!$A$3:$X$1500,MATCH('Suc. Xalisco'!$F$1,RAIZ!$A$2:$X$2,0),FALSE),0) -> 0 | D25: 3 | F25: =IF(D25-C25>=0,D25-C25,0) -> 3 | G25: 3
C26: =+IFERROR(VLOOKUP($A26,RAIZ!$A$3:$X$1500,MATCH('Suc. Xalisco'!$F$1,RAIZ!$A$2:$X$2,0),FALSE),0) -> 0 | F26: =IF(D26-C26>=0,D26-C26,0) -> 0
C27: =+IFERROR(VLOOKUP($A27,RAIZ!$A$3:$X$1500,MATCH('Suc. Xalisco'!$F$1,RAIZ!$A$2:$X$2,0),FALSE),0) -> 0 | F27: =IF(D27-C27>=0,D27-C27,0) -> 0
C28: =+IFERROR(VLOOKUP($A28,RAIZ!$A$3:$X$1500,MATCH('Suc. Xalisco'!$F$1,RAIZ!$A$2:$X$2,0),FALSE),0) -> 0 | F28: =IF(D28-C28>=0,D28-C28,0) -> 0
C29: =+IFERROR(VLOOKUP($A29,RAIZ!$A$3:$X$1500,MATCH('Suc. Xalisco'!$F$1,RAIZ!$A$2:$X$2,0),FALSE),0) -> 0 | F29: =IF(D29-C29>=0,D29-C29,0) -> 0
C30: =+IFERROR(VLOOKUP($A30,RAIZ!$A$3:$X$1500,MATCH('Suc. Xalisco'!$F$1,RAIZ!$A$2:$X$2,0),FALSE),0) -> 0 | F30: =IF(D30-C30>=0,D30-C30,0) -> 0
C31: =+IFERROR(VLOOKUP($A31,RAIZ!$A$3:$X$1500,MATCH('Suc. Xalisco'!$F$1,RAIZ!$A$2:$X$2,0),FALSE),0) -> 0 | F31: =IF(D31-C31>=0,D31-C31,0) -> 0
A32: 3 LECHES MEDIANOS | C32: =SUM(C19:C31) -> 7 | D32: =SUM(D19:D31) -> 14 | E32: =SUM(E19:E31) -> 0 | F32: =SUM(F19:F31) -> 7 | G32: =SUM(G19:G31) -> 6
A33: PIÑA CH | B33: 16 | C33: =+IFERROR(VLOOKUP($A33,RAIZ!$A$3:$X$1500,MATCH('Suc. Xalisco'!$F$1,RAIZ!$A$2:$X$2,0),FALSE),0) -> 2 | D33: 2 | F33: =IF(D33-C33>=0,D33-C33,0) -> 0
A34: DURAZNO CH | B34: 17 | C34: =+IFERROR(VLOOKUP($A34,RAIZ!$A$3:$X$1500,MATCH('Suc. Xalisco'!$F$1,RAIZ!$A$2:$X$2,0),FALSE),0) -> 2 | D34: 2 | F34: =IF(D34-C34>=0,D34-C34,0) -> 0
A35: FRESA CH | B35: 18 | C35: =+IFERROR(VLOOKUP($A35,RAIZ!$A$3:$X$1500,MATCH('Suc. Xalisco'!$F$1,RAIZ!$A$2:$X$2,0),FALSE),0) -> 2 | D35: 2 | F35: =IF(D35-C35>=0,D35-C35,0) -> 0
A36: 3 LECHES CH | B36: 19 | C36: =+IFERROR(VLOOKUP($A36,RAIZ!$A$3:$X$1500,MATCH('Suc. Xalisco'!$F$1,RAIZ!$A$2:$X$2,0),FALSE),0) -> 2 | D36: 2 | F36: =IF(D36-C36>=0,D36-C36,0) -> 0
A37: FRUTAS CH | B37: 20 | C37: =+IFERROR(VLOOKUP($A37,RAIZ!$A$3:$X$1500,MATCH('Suc. Xalisco'!$F$1,RAIZ!$A$2:$X$2,0),FALSE),0) -> 3 | D37: 3 | F37: =IF(D37-C37>=0,D37-C37,0) -> 0
A38: MOKA CH | B38: 23 | C38: =+IFERROR(VLOOKUP($A38,RAIZ!$A$3:$X$1500,MATCH('Suc. Xalisco'!$F$1,RAIZ!$A$2:$X$2,0),FALSE),0) -> 2 | D38: 3 | F38: =IF(D38-C38>=0,D38-C38,0) -> 1 | G38: 1
A39: NUTELA CH | B39: 28 | C39: =+IFERROR(VLOOKUP($A39,RAIZ!$A$3:$X$1500,MATCH('Suc. Xalisco'!$F$1,RAIZ!$A$2:$X$2,0),FALSE),0) -> 1 | D39: 2 | F39: =IF(D39-C39>=0,D39-C39,0) -> 1 | G39: 1
A40: CHOCOLATE CH | B40: 25 | C40: =+IFERROR(VLOOKUP($A40,RAIZ!$A$3:$X$1500,MATCH('Suc. Xalisco'!$F$1,RAIZ!$A$2:$X$2,0),FALSE),0) -> 0 | D40: 1 | F40: =IF(D40-C40>=0,D40-C40,0) -> 1 | G40: 1
...

Sheet Suc. Dos de Agosto
A1: =RAIZ!B1 -> 46301 | D1: SUCURSAL | F1: Suc. Dos de Agosto | H1: [ Suc. Dos de Agosto - Cantidad ]
A2: PRODUCTO | B2: CODIGO | C2: EXISTENCIA EN SUCURSAL | D2: STOCK DETERMINADO | E2: PROMEDIO DE DISTRIBUCIÓN | F2: PRODUCTO A COMPLETAR | G2: A SURTIR TICKET | H2: MARTES
A3: PIÑA GDE | B3: 02 | C3: =+IFERROR(VLOOKUP($A3,RAIZ!$A$3:$X$1500,MATCH('Suc. Dos de Agosto'!$F$1,RAIZ!$A$2:$X$2,0),FALSE),0) -> 1 | D3: 1 | F3: =IF(D3-C3>=0,D3-C3,0) -> 0
A4: DURAZNO GDE | B4: 04 | C4: =+IFERROR(VLOOKUP($A4,RAIZ!$A$3:$X$1500,MATCH('Suc. Dos de Agosto'!$F$1,RAIZ!$A$2:$X$2,0),FALSE),0) -> 2 | D4: 2 | F4: =IF(D4-C4>=0,D4-C4,0) -> 0
A5: 3 LECHES GDE | B5: 06 | C5: =+IFERROR(VLOOKUP($A5,RAIZ!$A$3:$X$1500,MATCH('Suc. Dos de Agosto'!$F$1,RAIZ!$A$2:$X$2,0),FALSE),0) -> 1 | D5: 1 | F5: =IF(D5-C5>=0,D5-C5,0) -> 0
A6: FRUTAS GDE | B6: 03 | C6: =+IFERROR(VLOOKUP($A6,RAIZ!$A$3:$X$1500,MATCH('Suc. Dos de Agosto'!$F$1,RAIZ!$A$2:$X$2,0),FALSE),0) -> 2 | D6: 2 | F6: =IF(D6-C6>=0,D6-C6,0) -> 0
A7: DUO DURAZNO GDE | B7: 13 | C7: =+IFERROR(VLOOKUP($A7,RAIZ!$A$3:$X$1500,MATCH('Suc. Dos de Agosto'!$F$1,RAIZ!$A$2:$X$2,0),FALSE),0) -> 1 | D7: 1 | F7: =IF(D7-C7>=0,D7-C7,0) -> 0
A8: MOKA GDE | B8: 01 | C8: =+IFERROR(VLOOKUP($A8,RAIZ!$A$3:$X$1500,MATCH('Suc. Dos de Agosto'!$F$1,RAIZ!$A$2:$X$2,0),FALSE),0) -> 2 | D8: 2 | F8: =IF(D8-C8>=0,D8-C8,0) -> 0
A9: NUTELA GDE | B9: 09 | C9: =+IFERROR(VLOOKUP($A9,RAIZ!$A$3:$X$1500,MATCH('Suc. Dos de Agosto'!$F$1,RAIZ!$A$2:$X$2,0),FALSE),0) -> 0 | D9: 2 | F9: =IF(D9-C9>=0,D9-C9,0) -> 2 | G9: 2
A10: CHOCOLATE GDE | B10: 07 | C10: =+IFERROR(VLOOKUP($A10,RAIZ!$A$3:$X$1500,MATCH('Suc. Dos de Agosto'!$F$1,RAIZ!$A$2:$X$2,0),FALSE),0) -> 1 | D10: 1 | F10: =IF(D10-C10>=0,D10-C10,0) -> 0
A11: M & M GDE | B11: 36 | C11: =+IFERROR(VLOOKUP($A11,RAIZ!$A$3:$X$1500,MATCH('Suc. Dos de Agosto'!$F$1,RAIZ!$A$2:$X$2,0),FALSE),0) -> 0 | D11: 2 | F11: =IF(D11-C11>=0,D11-C11,0) -> 2 | G11: 2
C12: =+IFERROR(VLOOKUP($A12,RAIZ!$A$3:$X$1500,MATCH('Suc. Dos de Agosto'!$F$1,RAIZ!$A$2:$X$2,0),FALSE),0) -> 0 | F12: =IF(D12-C12>=0,D12-C12,0) -> 0
C13: =+IFERROR(VLOOKUP($A13,RAIZ!$A$3:$X$1500,MATCH('Suc. Dos de Agosto'!$F$1,RAIZ!$A$2:$X$2,0),FALSE),0) -> 0 | F13: =IF(D13-C13>=0,D13-C13,0) -> 0
C14: =+IFERROR(VLOOKUP($A14,RAIZ!$A$3:$X$1500,MATCH('Suc. Dos de Agosto'!$F$1,RAIZ!$A$2:$X$2,0),FALSE),0) -> 0 | F14: =IF(D14-C14>=0,D14-C14,0) -> 0
C15: =+IFERROR(VLOOKUP($A15,RAIZ!$A$3:$X$1500,MATCH('Suc. Dos de Agosto'!$F$1,RAIZ!$A$2:$X$2,0),FALSE),0) -> 0 | F15: =IF(D15-C15>=0,D15-C15,0) -> 0
C16: =+IFERROR(VLOOKUP($A16,RAIZ!$A$3:$X$1500,MATCH('Suc. Dos de Agosto'!$F$1,RAIZ!$A$2:$X$2,0),FALSE),0) -> 0 | F16: =IF(D16-C16>=0,D16-C16,0) -> 0
C17: =+IFERROR(VLOOKUP($A17,RAIZ!$A$3:$X$1500,MATCH('Suc. Dos de Agosto'!$F$1,RAIZ!$A$2:$X$2,0),FALSE),0) -> 0 | F17: =IF(D17-C17>=0,D17-C17,0) -> 0
A18: 3 LECHES GRANDES | C18: =SUM(C3:C17) -> 10 | D18: =SUM(D3:D17) -> 14 | E18: =SUM(E3:E17) -> 0 | F18: =SUM(F3:F17) -> 4 | G18: =SUM(G3:G17) -> 4
A19: TRES LECHES MEDIANO | B19: 04M | C19: =+IFERROR(VLOOKUP($A19,RAIZ!$A$3:$X$1500,MATCH('Suc. Dos de Agosto'!$F$1,RAIZ!$A$2:$X$2,0),FALSE),0) -> 1 | D19: 1 | F19: =IF(D19-C19>=0,D19-C19,0) -> 0
A20: FRUTAS MED | B20: 23N | C20: =+IFERROR(VLOOKUP($A20,RAIZ!$A$3:$X$1500,MATCH('Suc. Dos de Agosto'!$F$1,RAIZ!$A$2:$X$2,0),FALSE),0) -> 3 | D20: 3 | F20: =IF(D20-C20>=0,D20-C20,0) -> 0
A21: DUO DURAZNO MEDIANO | B21: 06M | C21: =+IFERROR(VLOOKUP($A21,RAIZ!$A$3:$X$1500,MATCH('Suc. Dos de Agosto'!$F$1,RAIZ!$A$2:$X$2,0),FALSE),0) -> 1 | D21: 2 | F21: =IF(D21-C21>=0,D21-C21,0) -> 1 | G21: 1
A22: PIÑA MED | B22: 08M | C22: =+IFERROR(VLOOKUP($A22,RAIZ!$A$3:$X$1500,MATCH('Suc. Dos de Agosto'!$F$1,RAIZ!$A$2:$X$2,0),FALSE),0) -> 1 | D22: 1 | F22: =IF(D22-C22>=0,D22-C22,0) -> 0
A23: CHOCOLATE MED | B23: 24N | C23: =+IFERROR(VLOOKUP($A23,RAIZ!$A$3:$X$1500,MATCH('Suc. Dos de Agosto'!$F$1,RAIZ!$A$2:$X$2,0),FALSE),0) -> 2 | D23: 2 | F23: =IF(D23-C23>=0,D23-C23,0) -> 0
A24: M & M MEDIANO | B24: 07M | C24: =+IFERROR(VLOOKUP($A24,RAIZ!$A$3:$X$1500,MATCH('Suc. Dos de Agosto'!$F$1,RAIZ!$A$2:$X$2,0),FALSE),0) -> 0 | D24: 2 | F24: =IF(D24-C24>=0,D24-C24,0) -> 2
A25: MOKA MEDIANO | B25: 01M | C25: =+IFERROR(VLOOKUP($A25,RAIZ!$A$3:$X$1500,MATCH('Suc. Dos de Agosto'!$F$1,RAIZ!$A$2:$X$2,0),FALSE),0) -> 0 | D25: 2 | F25: =IF(D25-C25>=0,D25-C25,0) -> 2 | G25: 2
C26: =+IFERROR(VLOOKUP($A26,RAIZ!$A$3:$X$1500,MATCH('Suc. Dos de Agosto'!$F$1,RAIZ!$A$2:$X$2,0),FALSE),0) -> 0 | F26: =IF(D26-C26>=0,D26-C26,0) -> 0
C27: =+IFERROR(VLOOKUP($A27,RAIZ!$A$3:$X$1500,MATCH('Suc. Dos de Agosto'!$F$1,RAIZ!$A$2:$X$2,0),FALSE),0) -> 0 | F27: =IF(D27-C27>=0,D27-C27,0) -> 0
C28: =+IFERROR(VLOOKUP($A28,RAIZ!$A$3:$X$1500,MATCH('Suc. Dos de Agosto'!$F$1,RAIZ!$A$2:$X$2,0),FALSE),0) -> 0 | F28: =IF(D28-C28>=0,D28-C28,0) -> 0
C29: =+IFERROR(VLOOKUP($A29,RAIZ!$A$3:$X$1500,MATCH('Suc. Dos de Agosto'!$F$1,RAIZ!$A$2:$X$2,0),FALSE),0) -> 0 | F29: =IF(D29-C29>=0,D29-C29,0) -> 0
C30: =+IFERROR(VLOOKUP($A30,RAIZ!$A$3:$X$1500,MATCH('Suc. Dos de Agosto'!$F$1,RAIZ!$A$2:$X$2,0),FALSE),0) -> 0 | F30: =IF(D30-C30>=0,D30-C30,0) -> 0
C31: =+IFERROR(VLOOKUP($A31,RAIZ!$A$3:$X$1500,MATCH('Suc. Dos de Agosto'!$F$1,RAIZ!$A$2:$X$2,0),FALSE),0) -> 0 | F31: =IF(D31-C31>=0,D31-C31,0) -> 0
A32: 3 LECHES MEDIANOS | C32: =SUM(C19:C31) -> 8 | D32: =SUM(D19:D31) -> 13 | E32: =SUM(E19:E31) -> 0 | F32: =SUM(F19:F31) -> 5 | G32: =SUM(G19:G31) -> 3
A33: PIÑA CH | B33: 16 | C33: =+IFERROR(VLOOKUP($A33,RAIZ!$A$3:$X$1500,MATCH('Suc. Dos de Agosto'!$F$1,RAIZ!$A$2:$X$2,0),FALSE),0) -> 1 | D33: 2 | F33: =IF(D33-C33>=0,D33-C33,0) -> 1 | G33: 1
A34: DURAZNO CH | B34: 17 | C34: =+IFERROR(VLOOKUP($A34,RAIZ!$A$3:$X$1500,MATCH('Suc. Dos de Agosto'!$F$1,RAIZ!$A$2:$X$2,0),FALSE),0) -> 2 | D34: 2 | F34: =IF(D34-C34>=0,D34-C34,0) -> 0
A35: FRESA CH | B35: 18 | C35: =+IFERROR(VLOOKUP($A35,RAIZ!$A$3:$X$1500,MATCH('Suc. Dos de Agosto'!$F$1,RAIZ!$A$2:$X$2,0),FALSE),0) -> 1 | D35: 1 | F35: =IF(D35-C35>=0,D35-C35,0) -> 0
A36: 3 LECHES CH | B36: 19 | C36: =+IFERROR(VLOOKUP($A36,RAIZ!$A$3:$X$1500,MATCH('Suc. Dos de Agosto'!$F$1,RAIZ!$A$2:$X$2,0),FALSE),0) -> 0 | D36: 1 | F36: =IF(D36-C36>=0,D36-C36,0) -> 1 | G36: 1
A37: FRUTAS CH | B37: 20 | C37: =+IFERROR(VLOOKUP($A37,RAIZ!$A$3:$X$1500,MATCH('Suc. Dos de Agosto'!$F$1,RAIZ!$A$2:$X$2,0),FALSE),0) -> 2 | D37: 2 | F37: =IF(D37-C37>=0,D37-C37,0) -> 0
A38: MOKA CH | B38: 23 | C38: =+IFERROR(VLOOKUP($A38,RAIZ!$A$3:$X$1500,MATCH('Suc. Dos de Agosto'!$F$1,RAIZ!$A$2:$X$2,0),FALSE),0) -> 1 | D38: 3 | F38: =IF(D38-C38>=0,D38-C38,0) -> 2 | G38: 2
A39: NUTELA CH | B39: 28 | C39: =+IFERROR(VLOOKUP($A39,RAIZ!$A$3:$X$1500,MATCH('Suc. Dos de Agosto'!$F$1,RAIZ!$A$2:$X$2,0),FALSE),0) -> 1 | D39: 2 | F39: =IF(D39-C39>=0,D39-C39,0) -> 1 | G39: 1
A40: CHOCOLATE CH | B40: 25 | C40: =+IFERROR(VLOOKUP($A40,RAIZ!$A$3:$X$1500,MATCH('Suc. Dos de Agosto'!$F$1,RAIZ!$A$2:$X$2,0),FALSE),0) -> 2 | D40: 2 | F40: =IF(D40-C40>=0,D40-C40,0) -> 0
...

Sheet Suc. Mololoa
A1: =RAIZ!B1 -> 46301 | D1: SUCURSAL | F1: Suc. Mololoa | H1: [ Suc. Mololoa - Cantidad ]
A2: PRODUCTO | B2: CODIGO | C2: EXISTENCIA EN SUCURSAL | D2: STOCK DETERMINADO | E2: PROMEDIO DE DISTRIBUCIÓN | F2: PRODUCTO A COMPLETAR | G2: A SURTIR TICKET
A3: PIÑA GDE | B3: 02 | C3: =+IFERROR(VLOOKUP($A3,RAIZ!$A$3:$X$1500,MATCH('Suc. Mololoa'!$F$1,RAIZ!$A$2:$X$2,0),FALSE),0) -> 0 | D3: 1 | F3: =IF(D3-C3>=0,D3-C3,0) -> 1 | G3: 1
A4: DURAZNO GDE | B4: 04 | C4: =+IFERROR(VLOOKUP($A4,RAIZ!$A$3:$X$1500,MATCH('Suc. Mololoa'!$F$1,RAIZ!$A$2:$X$2,0),FALSE),0) -> 0 | D4: 2 | F4: =IF(D4-C4>=0,D4-C4,0) -> 2 | G4: 2
A5: 3 LECHES GDE | B5: 06 | C5: =+IFERROR(VLOOKUP($A5,RAIZ!$A$3:$X$1500,MATCH('Suc. Mololoa'!$F$1,RAIZ!$A$2:$X$2,0),FALSE),0) -> 1 | D5: 1 | F5: =IF(D5-C5>=0,D5-C5,0) -> 0
A6: FRUTAS GDE | B6: 03 | C6: =+IFERROR(VLOOKUP($A6,RAIZ!$A$3:$X$1500,MATCH('Suc. Mololoa'!$F$1,RAIZ!$A$2:$X$2,0),FALSE),0) -> 1 | D6: 2 | F6: =IF(D6-C6>=0,D6-C6,0) -> 1 | G6: 1
A7: DUO DURAZNO GDE | B7: 13 | C7: =+IFERROR(VLOOKUP($A7,RAIZ!$A$3:$X$1500,MATCH('Suc. Mololoa'!$F$1,RAIZ!$A$2:$X$2,0),FALSE),0) -> 0 | D7: 1 | F7: =IF(D7-C7>=0,D7-C7,0) -> 1 | G7: 1
A8: MOKA GDE | B8: 01 | C8: =+IFERROR(VLOOKUP($A8,RAIZ!$A$3:$X$1500,MATCH('Suc. Mololoa'!$F$1,RAIZ!$A$2:$X$2,0),FALSE),0) -> 1 | D8: 2 | F8: =IF(D8-C8>=0,D8-C8,0) -> 1 | G8: 1
A9: NUTELA GDE | B9: 09 | C9: =+IFERROR(VLOOKUP($A9,RAIZ!$A$3:$X$1500,MATCH('Suc. Mololoa'!$F$1,RAIZ!$A$2:$X$2,0),FALSE),0) -> 1 | D9: 1 | F9: =IF(D9-C9>=0,D9-C9,0) -> 0
A10: CHOCOLATE GDE | B10: 07 | C10: =+IFERROR(VLOOKUP($A10,RAIZ!$A$3:$X$1500,MATCH('Suc. Mololoa'!$F$1,RAIZ!$A$2:$X$2,0),FALSE),0) -> 2 | D10: 2 | F10: =IF(D10-C10>=0,D10-C10,0) -> 0
A11: M & M GDE | B11: 36 | C11: =+IFERROR(VLOOKUP($A11,RAIZ!$A$3:$X$1500,MATCH('Suc. Mololoa'!$F$1,RAIZ!$A$2:$X$2,0),FALSE),0) -> 0 | D11: 2 | F11: =IF(D11-C11>=0,D11-C11,0) -> 2 | G11: 2
C12: =+IFERROR(VLOOKUP($A12,RAIZ!$A$3:$X$1500,MATCH('Suc. Mololoa'!$F$1,RAIZ!$A$2:$X$2,0),FALSE),0) -> 0 | F12: =IF(D12-C12>=0,D12-C12,0) -> 0
C13: =+IFERROR(VLOOKUP($A13,RAIZ!$A$3:$X$1500,MATCH('Suc. Mololoa'!$F$1,RAIZ!$A$2:$X$2,0),FALSE),0) -> 0 | F13: =IF(D13-C13>=0,D13-C13,0) -> 0
C14: =+IFERROR(VLOOKUP($A14,RAIZ!$A$3:$X$1500,MATCH('Suc. Mololoa'!$F$1,RAIZ!$A$2:$X$2,0),FALSE),0) -> 0 | F14: =IF(D14-C14>=0,D14-C14,0) -> 0
C15: =+IFERROR(VLOOKUP($A15,RAIZ!$A$3:$X$1500,MATCH('Suc. Mololoa'!$F$1,RAIZ!$A$2:$X$2,0),FALSE),0) -> 0 | F15: =IF(D15-C15>=0,D15-C15,0) -> 0
C16: =+IFERROR(VLOOKUP($A16,RAIZ!$A$3:$X$1500,MATCH('Suc. Mololoa'!$F$1,RAIZ!$A$2:$X$2,0),FALSE),0) -> 0 | F16: =IF(D16-C16>=0,D16-C16,0) -> 0
C17: =+IFERROR(VLOOKUP($A17,RAIZ!$A$3:$X$1500,MATCH('Suc. Mololoa'!$F$1,RAIZ!$A$2:$X$2,0),FALSE),0) -> 0 | F17: =IF(D17-C17>=0,D17-C17,0) -> 0
A18: 3 LECHES GRANDES | C18: =SUM(C3:C17) -> 6 | D18: =SUM(D3:D17) -> 14 | E18: =SUM(E3:E17) -> 0 | F18: =SUM(F3:F17) -> 8 | G18: =SUM(G3:G17) -> 8
A19: TRES LECHES MEDIANO | B19: 04M | C19: =+IFERROR(VLOOKUP($A19,RAIZ!$A$3:$X$1500,MATCH('Suc. Mololoa'!$F$1,RAIZ!$A$2:$X$2,0),FALSE),0) -> 1 | D19: 1 | F19: =IF(D19-C19>=0,D19-C19,0) -> 0
A20: FRUTAS MED | B20: 23N | C20: =+IFERROR(VLOOKUP($A20,RAIZ!$A$3:$X$1500,MATCH('Suc. Mololoa'!$F$1,RAIZ!$A$2:$X$2,0),FALSE),0) -> 1 | D20: 2 | F20: =IF(D20-C20>=0,D20-C20,0) -> 1 | G20: 1
A21: DUO DURAZNO MEDIANO | B21: 06M | C21: =+IFERROR(VLOOKUP($A21,RAIZ!$A$3:$X$1500,MATCH('Suc. Mololoa'!$F$1,RAIZ!$A$2:$X$2,0),FALSE),0) -> 1 | D21: 1 | F21: =IF(D21-C21>=0,D21-C21,0) -> 0
A22: PIÑA MED | B22: 08M | C22: =+IFERROR(VLOOKUP($A22,RAIZ!$A$3:$X$1500,MATCH('Suc. Mololoa'!$F$1,RAIZ!$A$2:$X$2,0),FALSE),0) -> 0 | D22: 1 | F22: =IF(D22-C22>=0,D22-C22,0) -> 1 | G22: 1
A23: CHOCOLATE MED | B23: 24N | C23: =+IFERROR(VLOOKUP($A23,RAIZ!$A$3:$X$1500,MATCH('Suc. Mololoa'!$F$1,RAIZ!$A$2:$X$2,0),FALSE),0) -> 2 | D23: 2 | F23: =IF(D23-C23>=0,D23-C23,0) -> 0
A24: M & M MEDIANO | B24: 07M | C24: =+IFERROR(VLOOKUP($A24,RAIZ!$A$3:$X$1500,MATCH('Suc. Mololoa'!$F$1,RAIZ!$A$2:$X$2,0),FALSE),0) -> 0 | D24: 2 | F24: =IF(D24-C24>=0,D24-C24,0) -> 2
A25: MOKA MEDIANO | B25: 01M | C25: =+IFERROR(VLOOKUP($A25,RAIZ!$A$3:$X$1500,MATCH('Suc. Mololoa'!$F$1,RAIZ!$A$2:$X$2,0),FALSE),0) -> 0 | D25: 3 | F25: =IF(D25-C25>=0,D25-C25,0) -> 3 | G25: 3
C26: =+IFERROR(VLOOKUP($A26,RAIZ!$A$3:$X$1500,MATCH('Suc. Mololoa'!$F$1,RAIZ!$A$2:$X$2,0),FALSE),0) -> 0 | F26: =IF(D26-C26>=0,D26-C26,0) -> 0
C27: =+IFERROR(VLOOKUP($A27,RAIZ!$A$3:$X$1500,MATCH('Suc. Mololoa'!$F$1,RAIZ!$A$2:$X$2,0),FALSE),0) -> 0 | F27: =IF(D27-C27>=0,D27-C27,0) -> 0
C28: =+IFERROR(VLOOKUP($A28,RAIZ!$A$3:$X$1500,MATCH('Suc. Mololoa'!$F$1,RAIZ!$A$2:$X$2,0),FALSE),0) -> 0 | F28: =IF(D28-C28>=0,D28-C28,0) -> 0
C29: =+IFERROR(VLOOKUP($A29,RAIZ!$A$3:$X$1500,MATCH('Suc. Mololoa'!$F$1,RAIZ!$A$2:$X$2,0),FALSE),0) -> 0 | F29: =IF(D29-C29>=0,D29-C29,0) -> 0
C30: =+IFERROR(VLOOKUP($A30,RAIZ!$A$3:$X$1500,MATCH('Suc. Mololoa'!$F$1,RAIZ!$A$2:$X$2,0),FALSE),0) -> 0 | F30: =IF(D30-C30>=0,D30-C30,0) -> 0
C31: =+IFERROR(VLOOKUP($A31,RAIZ!$A$3:$X$1500,MATCH('Suc. Mololoa'!$F$1,RAIZ!$A$2:$X$2,0),FALSE),0) -> 0 | F31: =IF(D31-C31>=0,D31-C31,0) -> 0
A32: 3 LECHES MEDIANOS | C32: =SUM(C19:C31) -> 5 | D32: =SUM(D19:D31) -> 12 | E32: =SUM(E19:E31) -> 0 | F32: =SUM(F19:F31) -> 7 | G32: =SUM(G19:G31) -> 5
A33: PIÑA CH | B33: 16 | C33: =+IFERROR(VLOOKUP($A33,RAIZ!$A$3:$X$1500,MATCH('Suc. Mololoa'!$F$1,RAIZ!$A$2:$X$2,0),FALSE),0) -> 2 | D33: 2 | F33: =IF(D33-C33>=0,D33-C33,0) -> 0
A34: DURAZNO CH | B34: 17 | C34: =+IFERROR(VLOOKUP($A34,RAIZ!$A$3:$X$1500,MATCH('Suc. Mololoa'!$F$1,RAIZ!$A$2:$X$2,0),FALSE),0) -> 2 | D34: 2 | F34: =IF(D34-C34>=0,D34-C34,0) -> 0
A35: FRESA CH | B35: 18 | C35: =+IFERROR(VLOOKUP($A35,RAIZ!$A$3:$X$1500,MATCH('Suc. Mololoa'!$F$1,RAIZ!$A$2:$X$2,0),FALSE),0) -> 1 | D35: 2 | F35: =IF(D35-C35>=0,D35-C35,0) -> 1 | G35: 1
A36: 3 LECHES CH | B36: 19 | C36: =+IFERROR(VLOOKUP($A36,RAIZ!$A$3:$X$1500,MATCH('Suc. Mololoa'!$F$1,RAIZ!$A$2:$X$2,0),FALSE),0) -> 1 | D36: 1 | F36: =IF(D36-C36>=0,D36-C36,0) -> 0
A37: FRUTAS CH | B37: 20 | C37: =+IFERROR(VLOOKUP($A37,RAIZ!$A$3:$X$1500,MATCH('Suc. Mololoa'!$F$1,RAIZ!$A$2:$X$2,0),FALSE),0) -> 2 | D37: 2 | F37: =IF(D37-C37>=0,D37-C37,0) -> 0
A38: MOKA CH | B38: 23 | C38: =+IFERROR(VLOOKUP($A38,RAIZ!$A$3:$X$1500,MATCH('Suc. Mololoa'!$F$1,RAIZ!$A$2:$X$2,0),FALSE),0) -> 2 | D38: 3 | F38: =IF(D38-C38>=0,D38-C38,0) -> 1 | G38: 1
A39: NUTELA CH | B39: 28 | C39: =+IFERROR(VLOOKUP($A39,RAIZ!$A$3:$X$1500,MATCH('Suc. Mololoa'!$F$1,RAIZ!$A$2:$X$2,0),FALSE),0) -> 2 | D39: 2 | F39: =IF(D39-C39>=0,D39-C39,0) -> 0
A40: CHOCOLATE CH | B40: 25 | C40: =+IFERROR(VLOOKUP($A40,RAIZ!$A$3:$X$1500,MATCH('Suc. Mololoa'!$F$1,RAIZ!$A$2:$X$2,0),FALSE),0) -> 2 | D40: 2 | F40: =IF(D40-C40>=0,D40-C40,0) -> 0
...

Sheet Suc. Boulevard
A1: =RAIZ!B1 -> 46301 | D1: SUCURSAL | F1: Suc. Boulevard | H1: [ Suc. Boulevard - Cantidad ]
A2: PRODUCTO | B2: CODIGO | C2: EXISTENCIA EN SUCURSAL | D2: STOCK DETERMINADO | E2: PROMEDIO DE DISTRIBUCIÓN | F2: PRODUCTO A COMPLETAR | G2: A SURTIR TICKET | H2: MARTES
A3: PIÑA GDE | B3: 02 | C3: =+IFERROR(VLOOKUP($A3,RAIZ!$A$3:$X$1500,MATCH('Suc. Boulevard'!$F$1,RAIZ!$A$2:$X$2,0),FALSE),0) -> 1 | D3: 2 | F3: =IF(D3-C3>=0,D3-C3,0) -> 1 | G3: 1
A4: DURAZNO GDE | B4: 04 | C4: =+IFERROR(VLOOKUP($A4,RAIZ!$A$3:$X$1500,MATCH('Suc. Boulevard'!$F$1,RAIZ!$A$2:$X$2,0),FALSE),0) -> 2 | D4: 2 | F4: =IF(D4-C4>=0,D4-C4,0) -> 0
A5: 3 LECHES GDE | B5: 06 | C5: =+IFERROR(VLOOKUP($A5,RAIZ!$A$3:$X$1500,MATCH('Suc. Boulevard'!$F$1,RAIZ!$A$2:$X$2,0),FALSE),0) -> 1 | D5: 2 | F5: =IF(D5-C5>=0,D5-C5,0) -> 1 | G5: 1
A6: FRUTAS GDE | B6: 03 | C6: =+IFERROR(VLOOKUP($A6,RAIZ!$A$3:$X$1500,MATCH('Suc. Boulevard'!$F$1,RAIZ!$A$2:$X$2,0),FALSE),0) -> 3 | D6: 3 | F6: =IF(D6-C6>=0,D6-C6,0) -> 0
A7: DUO DURAZNO GDE | B7: 13 | C7: =+IFERROR(VLOOKUP($A7,RAIZ!$A$3:$X$1500,MATCH('Suc. Boulevard'!$F$1,RAIZ!$A$2:$X$2,0),FALSE),0) -> 1 | D7: 1 | F7: =IF(D7-C7>=0,D7-C7,0) -> 0
A8: MOKA GDE | B8: 01 | C8: =+IFERROR(VLOOKUP($A8,RAIZ!$A$3:$X$1500,MATCH('Suc. Boulevard'!$F$1,RAIZ!$A$2:$X$2,0),FALSE),0) -> 2 | D8: 2 | F8: =IF(D8-C8>=0,D8-C8,0) -> 0
A9: NUTELA GDE | B9: 09 | C9: =+IFERROR(VLOOKUP($A9,RAIZ!$A$3:$X$1500,MATCH('Suc. Boulevard'!$F$1,RAIZ!$A$2:$X$2,0),FALSE),0) -> 2 | D9: 2 | F9: =IF(D9-C9>=0,D9-C9,0) -> 0
A10: CHOCOLATE GDE | B10: 07 | C10: =+IFERROR(VLOOKUP($A10,RAIZ!$A$3:$X$1500,MATCH('Suc. Boulevard'!$F$1,RAIZ!$A$2:$X$2,0),FALSE),0) -> 2 | D10: 2 | F10: =IF(D10-C10>=0,D10-C10,0) -> 0
A11: M & M GDE | B11: 36 | C11: =+IFERROR(VLOOKUP($A11,RAIZ!$A$3:$X$1500,MATCH('Suc. Boulevard'!$F$1,RAIZ!$A$2:$X$2,0),FALSE),0) -> 1 | D11: 1 | F11: =IF(D11-C11>=0,D11-C11,0) -> 0
C12: =+IFERROR(VLOOKUP($A12,RAIZ!$A$3:$X$1500,MATCH('Suc. Boulevard'!$F$1,RAIZ!$A$2:$X$2,0),FALSE),0) -> 0 | F12: =IF(D12-C12>=0,D12-C12,0) -> 0
C13: =+IFERROR(VLOOKUP($A13,RAIZ!$A$3:$X$1500,MATCH('Suc. Boulevard'!$F$1,RAIZ!$A$2:$X$2,0),FALSE),0) -> 0 | F13: =IF(D13-C13>=0,D13-C13,0) -> 0
C14: =+IFERROR(VLOOKUP($A14,RAIZ!$A$3:$X$1500,MATCH('Suc. Boulevard'!$F$1,RAIZ!$A$2:$X$2,0),FALSE),0) -> 0 | F14: =IF(D14-C14>=0,D14-C14,0) -> 0
C15: =+IFERROR(VLOOKUP($A15,RAIZ!$A$3:$X$1500,MATCH('Suc. Boulevard'!$F$1,RAIZ!$A$2:$X$2,0),FALSE),0) -> 0 | F15: =IF(D15-C15>=0,D15-C15,0) -> 0
C16: =+IFERROR(VLOOKUP($A16,RAIZ!$A$3:$X$1500,MATCH('Suc. Boulevard'!$F$1,RAIZ!$A$2:$X$2,0),FALSE),0) -> 0 | F16: =IF(D16-C16>=0,D16-C16,0) -> 0
C17: =+IFERROR(VLOOKUP($A17,RAIZ!$A$3:$X$1500,MATCH('Suc. Boulevard'!$F$1,RAIZ!$A$2:$X$2,0),FALSE),0) -> 0 | F17: =IF(D17-C17>=0,D17-C17,0) -> 0
A18: 3 LECHES GRANDES | C18: =SUM(C3:C17) -> 15 | D18: =SUM(D3:D17) -> 17 | E18: =SUM(E3:E17) -> 0 | F18: =SUM(F3:F17) -> 2 | G18: =SUM(G3:G17) -> 2
A19: TRES LECHES MEDIANO | B19: 04M | C19: =+IFERROR(VLOOKUP($A19,RAIZ!$A$3:$X$1500,MATCH('Suc. Boulevard'!$F$1,RAIZ!$A$2:$X$2,0),FALSE),0) -> 0 | D19: 0 | F19: =IF(D19-C19>=0,D19-C19,0) -> 0
A20: FRUTAS MED | B20: 23N | C20: =+IFERROR(VLOOKUP($A20,RAIZ!$A$3:$X$1500,MATCH('Suc. Boulevard'!$F$1,RAIZ!$A$2:$X$2,0),FALSE),0) -> 2 | D20: 3 | F20: =IF(D20-C20>=0,D20-C20,0) -> 1 | G20: 1
A21: DUO DURAZNO MEDIANO | B21: 06M | C21: =+IFERROR(VLOOKUP($A21,RAIZ!$A$3:$X$1500,MATCH('Suc. Boulevard'!$F$1,RAIZ!$A$2:$X$2,0),FALSE),0) -> 1 | D21: 1 | F21: =IF(D21-C21>=0,D21-C21,0) -> 0
A22: PIÑA MED | B22: 08M | C22: =+IFERROR(VLOOKUP($A22,RAIZ!$A$3:$X$1500,MATCH('Suc. Boulevard'!$F$1,RAIZ!$A$2:$X$2,0),FALSE),0) -> 1 | D22: 1 | F22: =IF(D22-C22>=0,D22-C22,0) -> 0
A23: CHOCOLATE MED | B23: 24N | C23: =+IFERROR(VLOOKUP($A23,RAIZ!$A$3:$X$1500,MATCH('Suc. Boulevard'!$F$1,RAIZ!$A$2:$X$2,0),FALSE),0) -> 2 | D23: 2 | F23: =IF(D23-C23>=0,D23-C23,0) -> 0
A24: M & M MEDIANO | B24: 07M | C24: =+IFERROR(VLOOKUP($A24,RAIZ!$A$3:$X$1500,MATCH('Suc. Boulevard'!$F$1,RAIZ!$A$2:$X$2,0),FALSE),0) -> 0 | D24: 1 | F24: =IF(D24-C24>=0,D24-C24,0) -> 1
A25: MOKA MEDIANO | B25: 01M | C25: =+IFERROR(VLOOKUP($A25,RAIZ!$A$3:$X$1500,MATCH('Suc. Boulevard'!$F$1,RAIZ!$A$2:$X$2,0),FALSE),0) -> 0 | D25: 3 | F25: =IF(D25-C25>=0,D25-C25,0) -> 3 | G25: 3
C26: =+IFERROR(VLOOKUP($A26,RAIZ!$A$3:$X$1500,MATCH('Suc. Boulevard'!$F$1,RAIZ!$A$2:$X$2,0),FALSE),0) -> 0 | F26: =IF(D26-C26>=0,D26-C26,0) -> 0
C27: =+IFERROR(VLOOKUP($A27,RAIZ!$A$3:$X$1500,MATCH('Suc. Boulevard'!$F$1,RAIZ!$A$2:$X$2,0),FALSE),0) -> 0 | F27: =IF(D27-C27>=0,D27-C27,0) -> 0
C28: =+IFERROR(VLOOKUP($A28,RAIZ!$A$3:$X$1500,MATCH('Suc. Boulevard'!$F$1,RAIZ!$A$2:$X$2,0),FALSE),0) -> 0 | F28: =IF(D28-C28>=0,D28-C28,0) -> 0
C29: =+IFERROR(VLOOKUP($A29,RAIZ!$A$3:$X$1500,MATCH('Suc. Boulevard'!$F$1,RAIZ!$A$2:$X$2,0),FALSE),0) -> 0 | F29: =IF(D29-C29>=0,D29-C29,0) -> 0
C30: =+IFERROR(VLOOKUP($A30,RAIZ!$A$3:$X$1500,MATCH('Suc. Boulevard'!$F$1,RAIZ!$A$2:$X$2,0),FALSE),0) -> 0 | F30: =IF(D30-C30>=0,D30-C30,0) -> 0
C31: =+IFERROR(VLOOKUP($A31,RAIZ!$A$3:$X$1500,MATCH('Suc. Boulevard'!$F$1,RAIZ!$A$2:$X$2,0),FALSE),0) -> 0 | F31: =IF(D31-C31>=0,D31-C31,0) -> 0
A32: 3 LECHES MEDIANOS | C32: =SUM(C19:C31) -> 6 | D32: =SUM(D19:D31) -> 11 | E32: =SUM(E19:E31) -> 0 | F32: =SUM(F19:F31) -> 5 | G32: =SUM(G19:G31) -> 4
A33: PIÑA CH | B33: 16 | C33: =+IFERROR(VLOOKUP($A33,RAIZ!$A$3:$X$1500,MATCH('Suc. Boulevard'!$F$1,RAIZ!$A$2:$X$2,0),FALSE),0) -> 1 | D33: 2 | F33: =IF(D33-C33>=0,D33-C33,0) -> 1 | G33: 1
A34: DURAZNO CH | B34: 17 | C34: =+IFERROR(VLOOKUP($A34,RAIZ!$A$3:$X$1500,MATCH('Suc. Boulevard'!$F$1,RAIZ!$A$2:$X$2,0),FALSE),0) -> 0 | D34: 1 | F34: =IF(D34-C34>=0,D34-C34,0) -> 1 | G34: 1
A35: FRESA CH | B35: 18 | C35: =+IFERROR(VLOOKUP($A35,RAIZ!$A$3:$X$1500,MATCH('Suc. Boulevard'!$F$1,RAIZ!$A$2:$X$2,0),FALSE),0) -> 1 | D35: 1 | F35: =IF(D35-C35>=0,D35-C35,0) -> 0
A36: 3 LECHES CH | B36: 19 | C36: =+IFERROR(VLOOKUP($A36,RAIZ!$A$3:$X$1500,MATCH('Suc. Boulevard'!$F$1,RAIZ!$A$2:$X$2,0),FALSE),0) -> 0 | D36: 0 | F36: =IF(D36-C36>=0,D36-C36,0) -> 0
A37: FRUTAS CH | B37: 20 | C37: =+IFERROR(VLOOKUP($A37,RAIZ!$A$3:$X$1500,MATCH('Suc. Boulevard'!$F$1,RAIZ!$A$2:$X$2,0),FALSE),0) -> 3 | D37: 3 | F37: =IF(D37-C37>=0,D37-C37,0) -> 0
A38: MOKA CH | B38: 23 | C38: =+IFERROR(VLOOKUP($A38,RAIZ!$A$3:$X$1500,MATCH('Suc. Boulevard'!$F$1,RAIZ!$A$2:$X$2,0),FALSE),0) -> 2 | D38: 2 | F38: =IF(D38-C38>=0,D38-C38,0) -> 0
A39: NUTELA CH | B39: 28 | C39: =+IFERROR(VLOOKUP($A39,RAIZ!$A$3:$X$1500,MATCH('Suc. Boulevard'!$F$1,RAIZ!$A$2:$X$2,0),FALSE),0) -> 1 | D39: 1 | F39: =IF(D39-C39>=0,D39-C39,0) -> 0
A40: CHOCOLATE CH | B40: 25 | C40: =+IFERROR(VLOOKUP($A40,RAIZ!$A$3:$X$1500,MATCH('Suc. Boulevard'!$F$1,RAIZ!$A$2:$X$2,0),FALSE),0) -> 1 | D40: 2 | F40: =IF(D40-C40>=0,D40-C40,0) -> 1 | G40: 1
...

Sheet Suc. Plaza
A1: =RAIZ!B1 -> 46301 | D1: SUCURSAL | F1: Suc. Plaza | H1: [ Suc. Plaza - Cantidad ]
A2: PRODUCTO | B2: CODIGO | C2: EXISTENCIA EN SUCURSAL | D2: STOCK DETERMINADO | E2: PROMEDIO DE DISTRIBUCIÓN | F2: PRODUCTO A COMPLETAR | G2: A SURTIR TICKET | H2: MARTES
A3: PIÑA GDE | B3: 02 | C3: =+IFERROR(VLOOKUP($A3,RAIZ!$A$3:$X$1500,MATCH('Suc. Plaza'!$F$1,RAIZ!$A$2:$X$2,0),FALSE),0) -> 0 | D3: 1 | F3: =IF(D3-C3>=0,D3-C3,0) -> 1 | G3: 1
A4: DURAZNO GDE | B4: 04 | C4: =+IFERROR(VLOOKUP($A4,RAIZ!$A$3:$X$1500,MATCH('Suc. Plaza'!$F$1,RAIZ!$A$2:$X$2,0),FALSE),0) -> 0 | D4: 1 | F4: =IF(D4-C4>=0,D4-C4,0) -> 1 | G4: 1
A5: 3 LECHES GDE | B5: 06 | C5: =+IFERROR(VLOOKUP($A5,RAIZ!$A$3:$X$1500,MATCH('Suc. Plaza'!$F$1,RAIZ!$A$2:$X$2,0),FALSE),0) -> 1 | D5: 1 | F5: =IF(D5-C5>=0,D5-C5,0) -> 0
A6: FRUTAS GDE | B6: 03 | C6: =+IFERROR(VLOOKUP($A6,RAIZ!$A$3:$X$1500,MATCH('Suc. Plaza'!$F$1,RAIZ!$A$2:$X$2,0),FALSE),0) -> 2 | D6: 2 | F6: =IF(D6-C6>=0,D6-C6,0) -> 0
A7: DUO DURAZNO GDE | B7: 13 | C7: =+IFERROR(VLOOKUP($A7,RAIZ!$A$3:$X$1500,MATCH('Suc. Plaza'!$F$1,RAIZ!$A$2:$X$2,0),FALSE),0) -> 1 | D7: 1 | F7: =IF(D7-C7>=0,D7-C7,0) -> 0
A8: MOKA GDE | B8: 01 | C8: =+IFERROR(VLOOKUP($A8,RAIZ!$A$3:$X$1500,MATCH('Suc. Plaza'!$F$1,RAIZ!$A$2:$X$2,0),FALSE),0) -> 0 | D8: 1 | F8: =IF(D8-C8>=0,D8-C8,0) -> 1 | G8: 1
A9: NUTELA GDE | B9: 09 | C9: =+IFERROR(VLOOKUP($A9,RAIZ!$A$3:$X$1500,MATCH('Suc. Plaza'!$F$1,RAIZ!$A$2:$X$2,0),FALSE),0) -> 0 | D9: 1 | F9: =IF(D9-C9>=0,D9-C9,0) -> 1 | G9: 1
A10: CHOCOLATE GDE | B10: 07 | C10: =+IFERROR(VLOOKUP($A10,RAIZ!$A$3:$X$1500,MATCH('Suc. Plaza'!$F$1,RAIZ!$A$2:$X$2,0),FALSE),0) -> 0 | D10: 1 | F10: =IF(D10-C10>=0,D10-C10,0) -> 1 | G10: 1
A11: M & M GDE | B11: 36 | C11: =+IFERROR(VLOOKUP($A11,RAIZ!$A$3:$X$1500,MATCH('Suc. Plaza'!$F$1,RAIZ!$A$2:$X$2,0),FALSE),0) -> 0 | D11: 1 | F11: =IF(D11-C11>=0,D11-C11,0) -> 1 | G11: 1
C12: =+IFERROR(VLOOKUP($A12,RAIZ!$A$3:$X$1500,MATCH('Suc. Plaza'!$F$1,RAIZ!$A$2:$X$2,0),FALSE),0) -> 0 | F12: =IF(D12-C12>=0,D12-C12,0) -> 0
C13: =+IFERROR(VLOOKUP($A13,RAIZ!$A$3:$X$1500,MATCH('Suc. Plaza'!$F$1,RAIZ!$A$2:$X$2,0),FALSE),0) -> 0 | F13: =IF(D13-C13>=0,D13-C13,0) -> 0
C14: =+IFERROR(VLOOKUP($A14,RAIZ!$A$3:$X$1500,MATCH('Suc. Plaza'!$F$1,RAIZ!$A$2:$X$2,0),FALSE),0) -> 0 | F14: =IF(D14-C14>=0,D14-C14,0) -> 0
C15: =+IFERROR(VLOOKUP($A15,RAIZ!$A$3:$X$1500,MATCH('Suc. Plaza'!$F$1,RAIZ!$A$2:$X$2,0),FALSE),0) -> 0 | F15: =IF(D15-C15>=0,D15-C15,0) -> 0
C16: =+IFERROR(VLOOKUP($A16,RAIZ!$A$3:$X$1500,MATCH('Suc. Plaza'!$F$1,RAIZ!$A$2:$X$2,0),FALSE),0) -> 0 | F16: =IF(D16-C16>=0,D16-C16,0) -> 0
C17: =+IFERROR(VLOOKUP($A17,RAIZ!$A$3:$X$1500,MATCH('Suc. Plaza'!$F$1,RAIZ!$A$2:$X$2,0),FALSE),0) -> 0 | F17: =IF(D17-C17>=0,D17-C17,0) -> 0
A18: 3 LECHES GRANDES | C18: =SUM(C3:C17) -> 4 | D18: =SUM(D3:D17) -> 10 | E18: =SUM(E3:E17) -> 0 | F18: =SUM(F3:F17) -> 6 | G18: =SUM(G3:G17) -> 6
A19: TRES LECHES MEDIANO | B19: 04M | C19: =+IFERROR(VLOOKUP($A19,RAIZ!$A$3:$X$1500,MATCH('Suc. Plaza'!$F$1,RAIZ!$A$2:$X$2,0),FALSE),0) -> 1 | D19: 1 | F19: =IF(D19-C19>=0,D19-C19,0) -> 0
A20: FRUTAS MED | B20: 23N | C20: =+IFERROR(VLOOKUP($A20,RAIZ!$A$3:$X$1500,MATCH('Suc. Plaza'!$F$1,RAIZ!$A$2:$X$2,0),FALSE),0) -> 1 | D20: 1 | F20: =IF(D20-C20>=0,D20-C20,0) -> 0
A21: DUO DURAZNO MEDIANO | B21: 06M | C21: =+IFERROR(VLOOKUP($A21,RAIZ!$A$3:$X$1500,MATCH('Suc. Plaza'!$F$1,RAIZ!$A$2:$X$2,0),FALSE),0) -> 0 | D21: 1 | F21: =IF(D21-C21>=0,D21-C21,0) -> 1 | G21: 1
A22: PIÑA MED | B22: 08M | C22: =+IFERROR(VLOOKUP($A22,RAIZ!$A$3:$X$1500,MATCH('Suc. Plaza'!$F$1,RAIZ!$A$2:$X$2,0),FALSE),0) -> 1 | D22: 1 | F22: =IF(D22-C22>=0,D22-C22,0) -> 0
A23: CHOCOLATE MED | B23: 24N | C23: =+IFERROR(VLOOKUP($A23,RAIZ!$A$3:$X$1500,MATCH('Suc. Plaza'!$F$1,RAIZ!$A$2:$X$2,0),FALSE),0) -> 0 | D23: 1 | F23: =IF(D23-C23>=0,D23-C23,0) -> 1 | G23: 1
A24: M & M MEDIANO | B24: 07M | C24: =+IFERROR(VLOOKUP($A24,RAIZ!$A$3:$X$1500,MATCH('Suc. Plaza'!$F$1,RAIZ!$A$2:$X$2,0),FALSE),0) -> 0 | D24: 1 | F24: =IF(D24-C24>=0,D24-C24,0) -> 1
A25: MOKA MEDIANO | B25: 01M | C25: =+IFERROR(VLOOKUP($A25,RAIZ!$A$3:$X$1500,MATCH('Suc. Plaza'!$F$1,RAIZ!$A$2:$X$2,0),FALSE),0) -> 1 | D25: 1 | F25: =IF(D25-C25>=0,D25-C25,0) -> 0
C26: =+IFERROR(VLOOKUP($A26,RAIZ!$A$3:$X$1500,MATCH('Suc. Plaza'!$F$1,RAIZ!$A$2:$X$2,0),FALSE),0) -> 0 | D26: 0 | F26: =IF(D26-C26>=0,D26-C26,0) -> 0
C27: =+IFERROR(VLOOKUP($A27,RAIZ!$A$3:$X$1500,MATCH('Suc. Plaza'!$F$1,RAIZ!$A$2:$X$2,0),FALSE),0) -> 0 | F27: =IF(D27-C27>=0,D27-C27,0) -> 0
C28: =+IFERROR(VLOOKUP($A28,RAIZ!$A$3:$X$1500,MATCH('Suc. Plaza'!$F$1,RAIZ!$A$2:$X$2,0),FALSE),0) -> 0 | F28: =IF(D28-C28>=0,D28-C28,0) -> 0
C29: =+IFERROR(VLOOKUP($A29,RAIZ!$A$3:$X$1500,MATCH('Suc. Plaza'!$F$1,RAIZ!$A$2:$X$2,0),FALSE),0) -> 0 | F29: =IF(D29-C29>=0,D29-C29,0) -> 0
C30: =+IFERROR(VLOOKUP($A30,RAIZ!$A$3:$X$1500,MATCH('Suc. Plaza'!$F$1,RAIZ!$A$2:$X$2,0),FALSE),0) -> 0 | F30: =IF(D30-C30>=0,D30-C30,0) -> 0
C31: =+IFERROR(VLOOKUP($A31,RAIZ!$A$3:$X$1500,MATCH('Suc. Plaza'!$F$1,RAIZ!$A$2:$X$2,0),FALSE),0) -> 0 | F31: =IF(D31-C31>=0,D31-C31,0) -> 0
A32: 3 LECHES MEDIANOS | C32: =SUM(C19:C31) -> 4 | D32: =SUM(D19:D31) -> 7 | E32: =SUM(E19:E31) -> 0 | F32: =SUM(F19:F31) -> 3 | G32: =SUM(G19:G31) -> 2
A33: PIÑA CH | B33: 16 | C33: =+IFERROR(VLOOKUP($A33,RAIZ!$A$3:$X$1500,MATCH('Suc. Plaza'!$F$1,RAIZ!$A$2:$X$2,0),FALSE),0) -> 1 | D33: 1 | F33: =IF(D33-C33>=0,D33-C33,0) -> 0
A34: DURAZNO CH | B34: 17 | C34: =+IFERROR(VLOOKUP($A34,RAIZ!$A$3:$X$1500,MATCH('Suc. Plaza'!$F$1,RAIZ!$A$2:$X$2,0),FALSE),0) -> 0 | D34: 1 | F34: =IF(D34-C34>=0,D34-C34,0) -> 1 | G34: 1
A35: FRESA CH | B35: 18 | C35: =+IFERROR(VLOOKUP($A35,RAIZ!$A$3:$X$1500,MATCH('Suc. Plaza'!$F$1,RAIZ!$A$2:$X$2,0),FALSE),0) -> 1 | D35: 1 | F35: =IF(D35-C35>=0,D35-C35,0) -> 0
A36: 3 LECHES CH | B36: 19 | C36: =+IFERROR(VLOOKUP($A36,RAIZ!$A$3:$X$1500,MATCH('Suc. Plaza'!$F$1,RAIZ!$A$2:$X$2,0),FALSE),0) -> 1 | D36: 1 | F36: =IF(D36-C36>=0,D36-C36,0) -> 0
A37: FRUTAS CH | B37: 20 | C37: =+IFERROR(VLOOKUP($A37,RAIZ!$A$3:$X$1500,MATCH('Suc. Plaza'!$F$1,RAIZ!$A$2:$X$2,0),FALSE),0) -> 0 | D37: 1 | F37: =IF(D37-C37>=0,D37-C37,0) -> 1 | G37: 1
A38: MOKA CH | B38: 23 | C38: =+IFERROR(VLOOKUP($A38,RAIZ!$A$3:$X$1500,MATCH('Suc. Plaza'!$F$1,RAIZ!$A$2:$X$2,0),FALSE),0) -> 0 | D38: 1 | F38: =IF(D38-C38>=0,D38-C38,0) -> 1 | G38: 1
A39: NUTELA CH | B39: 28 | C39: =+IFERROR(VLOOKUP($A39,RAIZ!$A$3:$X$1500,MATCH('Suc. Plaza'!$F$1,RAIZ!$A$2:$X$2,0),FALSE),0) -> 1 | D39: 1 | F39: =IF(D39-C39>=0,D39-C39,0) -> 0
A40: CHOCOLATE CH | B40: 25 | C40: =+IFERROR(VLOOKUP($A40,RAIZ!$A$3:$X$1500,MATCH('Suc. Plaza'!$F$1,RAIZ!$A$2:$X$2,0),FALSE),0) -> 0 | D40: 1 | F40: =IF(D40-C40>=0,D40-C40,0) -> 1 | G40: 1
...

Sheet San Cayetano
A1: =RAIZ!B1 -> 46301 | D1: SUCURSAL | F1: San Cayetano | H1: [ San Cayetano - Cantidad ]
A2: PRODUCTO | B2: CODIGO | C2: EXISTENCIA EN SUCURSAL | D2: STOCK DETERMINADO | E2: PROMEDIO DE DISTRIBUCIÓN | F2: PRODUCTO A COMPLETAR | G2: A SURTIR TICKET | H2: MARTES
